Workbook

Sheet DIÁRIO (2)
C2: =SUM(C4:C65) -> 0 | D2: =SUM(D4:D65) -> 25563.22 | E2: =SUM(E4:E65) -> 610.67 | F2: =SUM(F4:F65) -> 0 | G2: =SUM(G4:G65) -> 9840 | H2: =SUM(H4:H65) -> 0 | I2: =SUM(I4:I65) -> 71849.5 | J2: =SUM(J4:J65) -> 23973.66 | ... T2: =SUM(T4:T65) -> 104100 | U2: =SUM(C2:T2) -> 334330.49
C3: 45944 | D3: 45945 | E3: 45946 | F3: 45947 | G3: 45948 | H3: 45949 | I3: 45950 | J3: 45951 | K3: 45952 | L3: 45953 | M3: 45954 | N3: 45955 | O3: 45956 | P3: 45957 | Q3: 45958 | R3: 45959 | S3: 45960 | T3: 45961 | U3: TOTAL
B4: Tecidos | C4: =SUMIFS('CONTAS A PAGAR SIMULAÇÃO'!$N:$N,'CONTAS A PAGAR SIMULAÇÃO'!$K:$K,'DIÁRIO (2)'!C$3,'CONTAS A PAGAR SIMULAÇÃO'!$S:$S,'DIÁRIO (2)'!$B4) -> 0 | D4: =SUMIFS('CONTAS A PAGAR SIMULAÇÃO'!$N:$N,'CONTAS A PAGAR SIMULAÇÃO'!$K:$K,'DIÁRIO (2)'!D$3,'CONTAS A PAGAR SIMULAÇÃO'!$S:$S,'DIÁRIO (2)'!$B4) -> 14002.12 | E4: =SUMIFS('CONTAS A PAGAR SIMULAÇÃO'!$N:$N,'CONTAS A PAGAR SIMULAÇÃO'!$K:$K,'DIÁRIO (2)'!E$3,'CONTAS A PAGAR SIMULAÇÃO'!$S:$S,'DIÁRIO (2)'!$B4) -> 610.67 | F4: =SUMIFS('CONTAS A PAGAR SIMULAÇÃO'!$N:$N,'CONTAS A PAGAR SIMULAÇÃO'!$K:$K,'DIÁRIO (2)'!F$3,'CONTAS A PAGAR SIMULAÇÃO'!$S:$S,'DIÁRIO (2)'!$B4) -> 0 | G4: =SUMIFS('CONTAS A PAGAR SIMULAÇÃO'!$N:$N,'CONTAS A PAGAR SIMULAÇÃO'!$K:$K,'DIÁRIO (2)'!G$3,'CONTAS A PAGAR SIMULAÇÃO'!$S:$S,'DIÁRIO (2)'!$B4) -> 9840 | H4: =SUMIFS('CONTAS A PAGAR SIMULAÇÃO'!$N:$N,'CONTAS A PAGAR SIMULAÇÃO'!$K:$K,'DIÁRIO (2)'!H$3,'CONTAS A PAGAR SIMULAÇÃO'!$S:$S,'DIÁRIO (2)'!$B4) -> 0 | I4: =SUMIFS('CONTAS A PAGAR SIMULAÇÃO'!$N:$N,'CONTAS A PAGAR SIMULAÇÃO'!$K:$K,'DIÁRIO (2)'!I$3,'CONTAS A PAGAR SIMULAÇÃO'!$S:$S,'DIÁRIO (2)'!$B4) -> 22248.8 | J4: =SUMIFS('CONTAS A PAGAR SIMULAÇÃO'!$N:$N,'CONTAS A PAGAR SIMULAÇÃO'!$K:$K,'DIÁRIO (2)'!J$3,'CONTAS A PAGAR SIMULAÇÃO'!$S:$S,'DIÁRIO (2)'!$B4) -> 9840 | ... T4: =SUMIFS('CONTAS A PAGAR SIMULAÇÃO'!$N:$N,'CONTAS A PAGAR SIMULAÇÃO'!$K:$K,'DIÁRIO (2)'!T$3,'CONTAS A PAGAR SIMULAÇÃO'!$S:$S,'DIÁRIO (2)'!$B4) -> 0 | U4: =SUM(C4:T4) -> 108613.34
B5: Lavanderia | C5: =SUMIFS('CONTAS A PAGAR SIMULAÇÃO'!$N:$N,'CONTAS A PAGAR SIMULAÇÃO'!$K:$K,'DIÁRIO (2)'!C$3,'CONTAS A PAGAR SIMULAÇÃO'!$S:$S,'DIÁRIO (2)'!$B5) -> 0 | D5: =SUMIFS('CONTAS A PAGAR SIMULAÇÃO'!$N:$N,'CONTAS A PAGAR SIMULAÇÃO'!$K:$K,'DIÁRIO (2)'!D$3,'CONTAS A PAGAR SIMULAÇÃO'!$S:$S,'DIÁRIO (2)'!$B5) -> 5210 | E5: =SUMIFS('CONTAS A PAGAR SIMULAÇÃO'!$N:$N,'CONTAS A PAGAR SIMULAÇÃO'!$K:$K,'DIÁRIO (2)'!E$3,'CONTAS A PAGAR SIMULAÇÃO'!$S:$S,'DIÁRIO (2)'!$B5) -> 0 | F5: =SUMIFS('CONTAS A PAGAR SIMULAÇÃO'!$N:$N,'CONTAS A PAGAR SIMULAÇÃO'!$K:$K,'DIÁRIO (2)'!F$3,'CONTAS A PAGAR SIMULAÇÃO'!$S:$S,'DIÁRIO (2)'!$B5) -> 0 | G5: =SUMIFS('CONTAS A PAGAR SIMULAÇÃO'!$N:$N,'CONTAS A PAGAR SIMULAÇÃO'!$K:$K,'DIÁRIO (2)'!G$3,'CONTAS A PAGAR SIMULAÇÃO'!$S:$S,'DIÁRIO (2)'!$B5) -> 0 | H5: =SUMIFS('CONTAS A PAGAR SIMULAÇÃO'!$N:$N,'CONTAS A PAGAR SIMULAÇÃO'!$K:$K,'DIÁRIO (2)'!H$3,'CONTAS A PAGAR SIMULAÇÃO'!$S:$S,'DIÁRIO (2)'!$B5) -> 0 | I5: =SUMIFS('CONTAS A PAGAR SIMULAÇÃO'!$N:$N,'CONTAS A PAGAR SIMULAÇÃO'!$K:$K,'DIÁRIO (2)'!I$3,'CONTAS A PAGAR SIMULAÇÃO'!$S:$S,'DIÁRIO (2)'!$B5) -> 3620.5 | J5: =SUMIFS('CONTAS A PAGAR SIMULAÇÃO'!$N:$N,'CONTAS A PAGAR SIMULAÇÃO'!$K:$K,'DIÁRIO (2)'!J$3,'CONTAS A PAGAR SIMULAÇÃO'!$S:$S,'DIÁRIO (2)'!$B5) -> 0 | ... T5: =SUMIFS('CONTAS A PAGAR SIMULAÇÃO'!$N:$N,'CONTAS A PAGAR SIMULAÇÃO'!$K:$K,'DIÁRIO (2)'!T$3,'CONTAS A PAGAR SIMULAÇÃO'!$S:$S,'DIÁRIO (2)'!$B5) -> 0 | U5: =SUM(C5:T5) -> 15260.5
B6: Travete | C6: =SUMIFS('CONTAS A PAGAR SIMULAÇÃO'!$N:$N,'CONTAS A PAGAR SIMULAÇÃO'!$K:$K,'DIÁRIO (2)'!C$3,'CONTAS A PAGAR SIMULAÇÃO'!$S:$S,'DIÁRIO (2)'!$B6) -> 0 | D6: =SUMIFS('CONTAS A PAGAR SIMULAÇÃO'!$N:$N,'CONTAS A PAGAR SIMULAÇÃO'!$K:$K,'DIÁRIO (2)'!D$3,'CONTAS A PAGAR SIMULAÇÃO'!$S:$S,'DIÁRIO (2)'!$B6) -> 0 | E6: =SUMIFS('CONTAS A PAGAR SIMULAÇÃO'!$N:$N,'CONTAS A PAGAR SIMULAÇÃO'!$K:$K,'DIÁRIO (2)'!E$3,'CONTAS A PAGAR SIMULAÇÃO'!$S:$S,'DIÁRIO (2)'!$B6) -> 0 | F6: =SUMIFS('CONTAS A PAGAR SIMULAÇÃO'!$N:$N,'CONTAS A PAGAR SIMULAÇÃO'!$K:$K,'DIÁRIO (2)'!F$3,'CONTAS A PAGAR SIMULAÇÃO'!$S:$S,'DIÁRIO (2)'!$B6) -> 0 | G6: =SUMIFS('CONTAS A PAGAR SIMULAÇÃO'!$N:$N,'CONTAS A PAGAR SIMULAÇÃO'!$K:$K,'DIÁRIO (2)'!G$3,'CONTAS A PAGAR SIMULAÇÃO'!$S:$S,'DIÁRIO (2)'!$B6) -> 0 | H6: =SUMIFS('CONTAS A PAGAR SIMULAÇÃO'!$N:$N,'CONTAS A PAGAR SIMULAÇÃO'!$K:$K,'DIÁRIO (2)'!H$3,'CONTAS A PAGAR SIMULAÇÃO'!$S:$S,'DIÁRIO (2)'!$B6) -> 0 | I6: =SUMIFS('CONTAS A PAGAR SIMULAÇÃO'!$N:$N,'CONTAS A PAGAR SIMULAÇÃO'!$K:$K,'DIÁRIO (2)'!I$3,'CONTAS A PAGAR SIMULAÇÃO'!$S:$S,'DIÁRIO (2)'!$B6) -> 881 | J6: =SUMIFS('CONTAS A PAGAR SIMULAÇÃO'!$N:$N,'CONTAS A PAGAR SIMULAÇÃO'!$K:$K,'DIÁRIO (2)'!J$3,'CONTAS A PAGAR SIMULAÇÃO'!$S:$S,'DIÁRIO (2)'!$B6) -> 0 | ... T6: =SUMIFS('CONTAS A PAGAR SIMULAÇÃO'!$N:$N,'CONTAS A PAGAR SIMULAÇÃO'!$K:$K,'DIÁRIO (2)'!T$3,'CONTAS A PAGAR SIMULAÇÃO'!$S:$S,'DIÁRIO (2)'!$B6) -> 0 | U6: =SUM(C6:T6) -> 881
B7: Facção | C7: =SUMIFS('CONTAS A PAGAR SIMULAÇÃO'!$N:$N,'CONTAS A PAGAR SIMULAÇÃO'!$K:$K,'DIÁRIO (2)'!C$3,'CONTAS A PAGAR SIMULAÇÃO'!$S:$S,'DIÁRIO (2)'!$B7) -> 0 | D7: =SUMIFS('CONTAS A PAGAR SIMULAÇÃO'!$N:$N,'CONTAS A PAGAR SIMULAÇÃO'!$K:$K,'DIÁRIO (2)'!D$3,'CONTAS A PAGAR SIMULAÇÃO'!$S:$S,'DIÁRIO (2)'!$B7) -> 0 | E7: =SUMIFS('CONTAS A PAGAR SIMULAÇÃO'!$N:$N,'CONTAS A PAGAR SIMULAÇÃO'!$K:$K,'DIÁRIO (2)'!E$3,'CONTAS A PAGAR SIMULAÇÃO'!$S:$S,'DIÁRIO (2)'!$B7) -> 0 | F7: =SUMIFS('CONTAS A PAGAR SIMULAÇÃO'!$N:$N,'CONTAS A PAGAR SIMULAÇÃO'!$K:$K,'DIÁRIO (2)'!F$3,'CONTAS A PAGAR SIMULAÇÃO'!$S:$S,'DIÁRIO (2)'!$B7) -> 0 | G7: =SUMIFS('CONTAS A PAGAR SIMULAÇÃO'!$N:$N,'CONTAS A PAGAR SIMULAÇÃO'!$K:$K,'DIÁRIO (2)'!G$3,'CONTAS A PAGAR SIMULAÇÃO'!$S:$S,'DIÁRIO (2)'!$B7) -> 0 | H7: =SUMIFS('CONTAS A PAGAR SIMULAÇÃO'!$N:$N,'CONTAS A PAGAR SIMULAÇÃO'!$K:$K,'DIÁRIO (2)'!H$3,'CONTAS A PAGAR SIMULAÇÃO'!$S:$S,'DIÁRIO (2)'!$B7) -> 0 | I7: =SUMIFS('CONTAS A PAGAR SIMULAÇÃO'!$N:$N,'CONTAS A PAGAR SIMULAÇÃO'!$K:$K,'DIÁRIO (2)'!I$3,'CONTAS A PAGAR SIMULAÇÃO'!$S:$S,'DIÁRIO (2)'!$B7) -> 34977.5 | J7: =SUMIFS('CONTAS A PAGAR SIMULAÇÃO'!$N:$N,'CONTAS A PAGAR SIMULAÇÃO'!$K:$K,'DIÁRIO (2)'!J$3,'CONTAS A PAGAR SIMULAÇÃO'!$S:$S,'DIÁRIO (2)'!$B7) -> 0 | ... T7: =SUMIFS('CONTAS A PAGAR SIMULAÇÃO'!$N:$N,'CONTAS A PAGAR SIMULAÇÃO'!$K:$K,'DIÁRIO (2)'!T$3,'CONTAS A PAGAR SIMULAÇÃO'!$S:$S,'DIÁRIO (2)'!$B7) -> 0 | U7: =SUM(C7:T7) -> 46858
B8: Acabamento Externo | C8: =SUMIFS('CONTAS A PAGAR SIMULAÇÃO'!$N:$N,'CONTAS A PAGAR SIMULAÇÃO'!$K:$K,'DIÁRIO (2)'!C$3,'CONTAS A PAGAR SIMULAÇÃO'!$S:$S,'DIÁRIO (2)'!$B8) -> 0 | D8: =SUMIFS('CONTAS A PAGAR SIMULAÇÃO'!$N:$N,'CONTAS A PAGAR SIMULAÇÃO'!$K:$K,'DIÁRIO (2)'!D$3,'CONTAS A PAGAR SIMULAÇÃO'!$S:$S,'DIÁRIO (2)'!$B8) -> 0 | E8: =SUMIFS('CONTAS A PAGAR SIMULAÇÃO'!$N:$N,'CONTAS A PAGAR SIMULAÇÃO'!$K:$K,'DIÁRIO (2)'!E$3,'CONTAS A PAGAR SIMULAÇÃO'!$S:$S,'DIÁRIO (2)'!$B8) -> 0 | F8: =SUMIFS('CONTAS A PAGAR SIMULAÇÃO'!$N:$N,'CONTAS A PAGAR SIMULAÇÃO'!$K:$K,'DIÁRIO (2)'!F$3,'CONTAS A PAGAR SIMULAÇÃO'!$S:$S,'DIÁRIO (2)'!$B8) -> 0 | G8: =SUMIFS('CONTAS A PAGAR SIMULAÇÃO'!$N:$N,'CONTAS A PAGAR SIMULAÇÃO'!$K:$K,'DIÁRIO (2)'!G$3,'CONTAS A PAGAR SIMULAÇÃO'!$S:$S,'DIÁRIO (2)'!$B8) -> 0 | H8: =SUMIFS('CONTAS A PAGAR SIMULAÇÃO'!$N:$N,'CONTAS A PAGAR SIMULAÇÃO'!$K:$K,'DIÁRIO (2)'!H$3,'CONTAS A PAGAR SIMULAÇÃO'!$S:$S,'DIÁRIO (2)'!$B8) -> 0 | I8: =SUMIFS('CONTAS A PAGAR SIMULAÇÃO'!$N:$N,'CONTAS A PAGAR SIMULAÇÃO'!$K:$K,'DIÁRIO (2)'!I$3,'CONTAS A PAGAR SIMULAÇÃO'!$S:$S,'DIÁRIO (2)'!$B8) -> 0 | J8: =SUMIFS('CONTAS A PAGAR SIMULAÇÃO'!$N:$N,'CONTAS A PAGAR SIMULAÇÃO'!$K:$K,'DIÁRIO (2)'!J$3,'CONTAS A PAGAR SIMULAÇÃO'!$S:$S,'DIÁRIO (2)'!$B8) -> 0 | ... T8: =SUMIFS('CONTAS A PAGAR SIMULAÇÃO'!$N:$N,'CONTAS A PAGAR SIMULAÇÃO'!$K:$K,'DIÁRIO (2)'!T$3,'CONTAS A PAGAR SIMULAÇÃO'!$S:$S,'DIÁRIO (2)'!$B8) -> 0 | U8: =SUM(C8:T8) -> 0
B9: Aviamento | C9: =SUMIFS('CONTAS A PAGAR SIMULAÇÃO'!$N:$N,'CONTAS A PAGAR SIMULAÇÃO'!$K:$K,'DIÁRIO (2)'!C$3,'CONTAS A PAGAR SIMULAÇÃO'!$S:$S,'DIÁRIO (2)'!$B9) -> 0 | D9: =SUMIFS('CONTAS A PAGAR SIMULAÇÃO'!$N:$N,'CONTAS A PAGAR SIMULAÇÃO'!$K:$K,'DIÁRIO (2)'!D$3,'CONTAS A PAGAR SIMULAÇÃO'!$S:$S,'DIÁRIO (2)'!$B9) -> 2182.6 | E9: =SUMIFS('CONTAS A PAGAR SIMULAÇÃO'!$N:$N,'CONTAS A PAGAR SIMULAÇÃO'!$K:$K,'DIÁRIO (2)'!E$3,'CONTAS A PAGAR SIMULAÇÃO'!$S:$S,'DIÁRIO (2)'!$B9) -> 0 | F9: =SUMIFS('CONTAS A PAGAR SIMULAÇÃO'!$N:$N,'CONTAS A PAGAR SIMULAÇÃO'!$K:$K,'DIÁRIO (2)'!F$3,'CONTAS A PAGAR SIMULAÇÃO'!$S:$S,'DIÁRIO (2)'!$B9) -> 0 | G9: =SUMIFS('CONTAS A PAGAR SIMULAÇÃO'!$N:$N,'CONTAS A PAGAR SIMULAÇÃO'!$K:$K,'DIÁRIO (2)'!G$3,'CONTAS A PAGAR SIMULAÇÃO'!$S:$S,'DIÁRIO (2)'!$B9) -> 0 | H9: =SUMIFS('CONTAS A PAGAR SIMULAÇÃO'!$N:$N,'CONTAS A PAGAR SIMULAÇÃO'!$K:$K,'DIÁRIO (2)'!H$3,'CONTAS A PAGAR SIMULAÇÃO'!$S:$S,'DIÁRIO (2)'!$B9) -> 0 | I9: =SUMIFS('CONTAS A PAGAR SIMULAÇÃO'!$N:$N,'CONTAS A PAGAR SIMULAÇÃO'!$K:$K,'DIÁRIO (2)'!I$3,'CONTAS A PAGAR SIMULAÇÃO'!$S:$S,'DIÁRIO (2)'!$B9) -> 0 | J9: =SUMIFS('CONTAS A PAGAR SIMULAÇÃO'!$N:$N,'CONTAS A PAGAR SIMULAÇÃO'!$K:$K,'DIÁRIO (2)'!J$3,'CONTAS A PAGAR SIMULAÇÃO'!$S:$S,'DIÁRIO (2)'!$B9) -> 2000 | ... T9: =SUMIFS('CONTAS A PAGAR SIMULAÇÃO'!$N:$N,'CONTAS A PAGAR SIMULAÇÃO'!$K:$K,'DIÁRIO (2)'!T$3,'CONTAS A PAGAR SIMULAÇÃO'!$S:$S,'DIÁRIO (2)'!$B9) -> 0 | U9: =SUM(C9:T9) -> 10509.63
B10: Etiquetas | C10: =SUMIFS('CONTAS A PAGAR SIMULAÇÃO'!$N:$N,'CONTAS A PAGAR SIMULAÇÃO'!$K:$K,'DIÁRIO (2)'!C$3,'CONTAS A PAGAR SIMULAÇÃO'!$S:$S,'DIÁRIO (2)'!$B10) -> 0 | D10: =SUMIFS('CONTAS A PAGAR SIMULAÇÃO'!$N:$N,'CONTAS A PAGAR SIMULAÇÃO'!$K:$K,'DIÁRIO (2)'!D$3,'CONTAS A PAGAR SIMULAÇÃO'!$S:$S,'DIÁRIO (2)'!$B10) -> 0 | E10: =SUMIFS('CONTAS A PAGAR SIMULAÇÃO'!$N:$N,'CONTAS A PAGAR SIMULAÇÃO'!$K:$K,'DIÁRIO (2)'!E$3,'CONTAS A PAGAR SIMULAÇÃO'!$S:$S,'DIÁRIO (2)'!$B10) -> 0 | F10: =SUMIFS('CONTAS A PAGAR SIMULAÇÃO'!$N:$N,'CONTAS A PAGAR SIMULAÇÃO'!$K:$K,'DIÁRIO (2)'!F$3,'CONTAS A PAGAR SIMULAÇÃO'!$S:$S,'DIÁRIO (2)'!$B10) -> 0 | G10: =SUMIFS('CONTAS A PAGAR SIMULAÇÃO'!$N:$N,'CONTAS A PAGAR SIMULAÇÃO'!$K:$K,'DIÁRIO (2)'!G$3,'CONTAS A PAGAR SIMULAÇÃO'!$S:$S,'DIÁRIO (2)'!$B10) -> 0 | H10: =SUMIFS('CONTAS A PAGAR SIMULAÇÃO'!$N:$N,'CONTAS A PAGAR SIMULAÇÃO'!$K:$K,'DIÁRIO (2)'!H$3,'CONTAS A PAGAR SIMULAÇÃO'!$S:$S,'DIÁRIO (2)'!$B10) -> 0 | I10: =SUMIFS('CONTAS A PAGAR SIMULAÇÃO'!$N:$N,'CONTAS A PAGAR SIMULAÇÃO'!$K:$K,'DIÁRIO (2)'!I$3,'CONTAS A PAGAR SIMULAÇÃO'!$S:$S,'DIÁRIO (2)'!$B10) -> 0 | J10: =SUMIFS('CONTAS A PAGAR SIMULAÇÃO'!$N:$N,'CONTAS A PAGAR SIMULAÇÃO'!$K:$K,'DIÁRIO (2)'!J$3,'CONTAS A PAGAR SIMULAÇÃO'!$S:$S,'DIÁRIO (2)'!$B10) -> 0 | ... T10: =SUMIFS('CONTAS A PAGAR SIMULAÇÃO'!$N:$N,'CONTAS A PAGAR SIMULAÇÃO'!$K:$K,'DIÁRIO (2)'!T$3,'CONTAS A PAGAR SIMULAÇÃO'!$S:$S,'DIÁRIO (2)'!$B10) -> 0 | U10: =SUM(C10:T10) -> 5294
B11: Bordado Industrial | C11: =SUMIFS('CONTAS A PAGAR SIMULAÇÃO'!$N:$N,'CONTAS A PAGAR SIMULAÇÃO'!$K:$K,'DIÁRIO (2)'!C$3,'CONTAS A PAGAR SIMULAÇÃO'!$S:$S,'DIÁRIO (2)'!$B11) -> 0 | D11: =SUMIFS('CONTAS A PAGAR SIMULAÇÃO'!$N:$N,'CONTAS A PAGAR SIMULAÇÃO'!$K:$K,'DIÁRIO (2)'!D$3,'CONTAS A PAGAR SIMULAÇÃO'!$S:$S,'DIÁRIO (2)'!$B11) -> 0 | E11: =SUMIFS('CONTAS A PAGAR SIMULAÇÃO'!$N:$N,'CONTAS A PAGAR SIMULAÇÃO'!$K:$K,'DIÁRIO (2)'!E$3,'CONTAS A PAGAR SIMULAÇÃO'!$S:$S,'DIÁRIO (2)'!$B11) -> 0 | F11: =SUMIFS('CONTAS A PAGAR SIMULAÇÃO'!$N:$N,'CONTAS A PAGAR SIMULAÇÃO'!$K:$K,'DIÁRIO (2)'!F$3,'CONTAS A PAGAR SIMULAÇÃO'!$S:$S,'DIÁRIO (2)'!$B11) -> 0 | G11: =SUMIFS('CONTAS A PAGAR SIMULAÇÃO'!$N:$N,'CONTAS A PAGAR SIMULAÇÃO'!$K:$K,'DIÁRIO (2)'!G$3,'CONTAS A PAGAR SIMULAÇÃO'!$S:$S,'DIÁRIO (2)'!$B11) -> 0 | H11: =SUMIFS('CONTAS A PAGAR SIMULAÇÃO'!$N:$N,'CONTAS A PAGAR SIMULAÇÃO'!$K:$K,'DIÁRIO (2)'!H$3,'CONTAS A PAGAR SIMULAÇÃO'!$S:$S,'DIÁRIO (2)'!$B11) -> 0 | I11: =SUMIFS('CONTAS A PAGAR SIMULAÇÃO'!$N:$N,'CONTAS A PAGAR SIMULAÇÃO'!$K:$K,'DIÁRIO (2)'!I$3,'CONTAS A PAGAR SIMULAÇÃO'!$S:$S,'DIÁRIO (2)'!$B11) -> 0 | J11: =SUMIFS('CONTAS A PAGAR SIMULAÇÃO'!$N:$N,'CONTAS A PAGAR SIMULAÇÃO'!$K:$K,'DIÁRIO (2)'!J$3,'CONTAS A PAGAR SIMULAÇÃO'!$S:$S,'DIÁRIO (2)'!$B11) -> 0 | ... T11: =SUMIFS('CONTAS A PAGAR SIMULAÇÃO'!$N:$N,'CONTAS A PAGAR SIMULAÇÃO'!$K:$K,'DIÁRIO (2)'!T$3,'CONTAS A PAGAR SIMULAÇÃO'!$S:$S,'DIÁRIO (2)'!$B11) -> 0 | U11: =SUM(C11:T11) -> 0
B12: Embalagens | C12: =SUMIFS('CONTAS A PAGAR SIMULAÇÃO'!$N:$N,'CONTAS A PAGAR SIMULAÇÃO'!$K:$K,'DIÁRIO (2)'!C$3,'CONTAS A PAGAR SIMULAÇÃO'!$S:$S,'DIÁRIO (2)'!$B12) -> 0 | D12: =SUMIFS('CONTAS A PAGAR SIMULAÇÃO'!$N:$N,'CONTAS A PAGAR SIMULAÇÃO'!$K:$K,'DIÁRIO (2)'!D$3,'CONTAS A PAGAR SIMULAÇÃO'!$S:$S,'DIÁRIO (2)'!$B12) -> 0 | E12: =SUMIFS('CONTAS A PAGAR SIMULAÇÃO'!$N:$N,'CONTAS A PAGAR SIMULAÇÃO'!$K:$K,'DIÁRIO (2)'!E$3,'CONTAS A PAGAR SIMULAÇÃO'!$S:$S,'DIÁRIO (2)'!$B12) -> 0 | F12: =SUMIFS('CONTAS A PAGAR SIMULAÇÃO'!$N:$N,'CONTAS A PAGAR SIMULAÇÃO'!$K:$K,'DIÁRIO (2)'!F$3,'CONTAS A PAGAR SIMULAÇÃO'!$S:$S,'DIÁRIO (2)'!$B12) -> 0 | G12: =SUMIFS('CONTAS A PAGAR SIMULAÇÃO'!$N:$N,'CONTAS A PAGAR SIMULAÇÃO'!$K:$K,'DIÁRIO (2)'!G$3,'CONTAS A PAGAR SIMULAÇÃO'!$S:$S,'DIÁRIO (2)'!$B12) -> 0 | H12: =SUMIFS('CONTAS A PAGAR SIMULAÇÃO'!$N:$N,'CONTAS A PAGAR SIMULAÇÃO'!$K:$K,'DIÁRIO (2)'!H$3,'CONTAS A PAGAR SIMULAÇÃO'!$S:$S,'DIÁRIO (2)'!$B12) -> 0 | I12: =SUMIFS('CONTAS A PAGAR SIMULAÇÃO'!$N:$N,'CONTAS A PAGAR SIMULAÇÃO'!$K:$K,'DIÁRIO (2)'!I$3,'CONTAS A PAGAR SIMULAÇÃO'!$S:$S,'DIÁRIO (2)'!$B12) -> 0 | J12: =SUMIFS('CONTAS A PAGAR SIMULAÇÃO'!$N:$N,'CONTAS A PAGAR SIMULAÇÃO'!$K:$K,'DIÁRIO (2)'!J$3,'CONTAS A PAGAR SIMULAÇÃO'!$S:$S,'DIÁRIO (2)'!$B12) -> 0 | ... T12: =SUMIFS('CONTAS A PAGAR SIMULAÇÃO'!$N:$N,'CONTAS A PAGAR SIMULAÇÃO'!$K:$K,'DIÁRIO (2)'!T$3,'CONTAS A PAGAR SIMULAÇÃO'!$S:$S,'DIÁRIO (2)'!$B12) -> 0 | U12: =SUM(C12:T12) -> 0
B13: Criação de Modelos | C13: =SUMIFS('CONTAS A PAGAR SIMULAÇÃO'!$N:$N,'CONTAS A PAGAR SIMULAÇÃO'!$K:$K,'DIÁRIO (2)'!C$3,'CONTAS A PAGAR SIMULAÇÃO'!$S:$S,'DIÁRIO (2)'!$B13) -> 0 | D13: =SUMIFS('CONTAS A PAGAR SIMULAÇÃO'!$N:$N,'CONTAS A PAGAR SIMULAÇÃO'!$K:$K,'DIÁRIO (2)'!D$3,'CONTAS A PAGAR SIMULAÇÃO'!$S:$S,'DIÁRIO (2)'!$B13) -> 0 | E13: =SUMIFS('CONTAS A PAGAR SIMULAÇÃO'!$N:$N,'CONTAS A PAGAR SIMULAÇÃO'!$K:$K,'DIÁRIO (2)'!E$3,'CONTAS A PAGAR SIMULAÇÃO'!$S:$S,'DIÁRIO (2)'!$B13) -> 0 | F13: =SUMIFS('CONTAS A PAGAR SIMULAÇÃO'!$N:$N,'CONTAS A PAGAR SIMULAÇÃO'!$K:$K,'DIÁRIO (2)'!F$3,'CONTAS A PAGAR SIMULAÇÃO'!$S:$S,'DIÁRIO (2)'!$B13) -> 0 | G13: =SUMIFS('CONTAS A PAGAR SIMULAÇÃO'!$N:$N,'CONTAS A PAGAR SIMULAÇÃO'!$K:$K,'DIÁRIO (2)'!G$3,'CONTAS A PAGAR SIMULAÇÃO'!$S:$S,'DIÁRIO (2)'!$B13) -> 0 | H13: =SUMIFS('CONTAS A PAGAR SIMULAÇÃO'!$N:$N,'CONTAS A PAGAR SIMULAÇÃO'!$K:$K,'DIÁRIO (2)'!H$3,'CONTAS A PAGAR SIMULAÇÃO'!$S:$S,'DIÁRIO (2)'!$B13) -> 0 | I13: =SUMIFS('CONTAS A PAGAR SIMULAÇÃO'!$N:$N,'CONTAS A PAGAR SIMULAÇÃO'!$K:$K,'DIÁRIO (2)'!I$3,'CONTAS A PAGAR SIMULAÇÃO'!$S:$S,'DIÁRIO (2)'!$B13) -> 0 | J13: =SUMIFS('CONTAS A PAGAR SIMULAÇÃO'!$N:$N,'CONTAS A PAGAR SIMULAÇÃO'!$K:$K,'DIÁRIO (2)'!J$3,'CONTAS A PAGAR SIMULAÇÃO'!$S:$S,'DIÁRIO (2)'!$B13) -> 0 | ... T13: =SUMIFS('CONTAS A PAGAR SIMULAÇÃO'!$N:$N,'CONTAS A PAGAR SIMULAÇÃO'!$K:$K,'DIÁRIO (2)'!T$3,'CONTAS A PAGAR SIMULAÇÃO'!$S:$S,'DIÁRIO (2)'!$B13) -> 0 | U13: =SUM(C13:T13) -> 0
B14: Salário e Ordenados | C14: =SUMIFS('CONTAS A PAGAR SIMULAÇÃO'!$N:$N,'CONTAS A PAGAR SIMULAÇÃO'!$K:$K,'DIÁRIO (2)'!C$3,'CONTAS A PAGAR SIMULAÇÃO'!$S:$S,'DIÁRIO (2)'!$B14) -> 0 | D14: =SUMIFS('CONTAS A PAGAR SIMULAÇÃO'!$N:$N,'CONTAS A PAGAR SIMULAÇÃO'!$K:$K,'DIÁRIO (2)'!D$3,'CONTAS A PAGAR SIMULAÇÃO'!$S:$S,'DIÁRIO (2)'!$B14) -> 0 | E14: =SUMIFS('CONTAS A PAGAR SIMULAÇÃO'!$N:$N,'CONTAS A PAGAR SIMULAÇÃO'!$K:$K,'DIÁRIO (2)'!E$3,'CONTAS A PAGAR SIMULAÇÃO'!$S:$S,'DIÁRIO (2)'!$B14) -> 0 | F14: =SUMIFS('CONTAS A PAGAR SIMULAÇÃO'!$N:$N,'CONTAS A PAGAR SIMULAÇÃO'!$K:$K,'DIÁRIO (2)'!F$3,'CONTAS A PAGAR SIMULAÇÃO'!$S:$S,'DIÁRIO (2)'!$B14) -> 0 | G14: =SUMIFS('CONTAS A PAGAR SIMULAÇÃO'!$N:$N,'CONTAS A PAGAR SIMULAÇÃO'!$K:$K,'DIÁRIO (2)'!G$3,'CONTAS A PAGAR SIMULAÇÃO'!$S:$S,'DIÁRIO (2)'!$B14) -> 0 | H14: =SUMIFS('CONTAS A PAGAR SIMULAÇÃO'!$N:$N,'CONTAS A PAGAR SIMULAÇÃO'!$K:$K,'DIÁRIO (2)'!H$3,'CONTAS A PAGAR SIMULAÇÃO'!$S:$S,'DIÁRIO (2)'!$B14) -> 0 | I14: =SUMIFS('CONTAS A PAGAR SIMULAÇÃO'!$N:$N,'CONTAS A PAGAR SIMULAÇÃO'!$K:$K,'DIÁRIO (2)'!I$3,'CONTAS A PAGAR SIMULAÇÃO'!$S:$S,'DIÁRIO (2)'!$B14) -> 170 | J14: =SUMIFS('CONTAS A PAGAR SIMULAÇÃO'!$N:$N,'CONTAS A PAGAR SIMULAÇÃO'!$K:$K,'DIÁRIO (2)'!J$3,'CONTAS A PAGAR SIMULAÇÃO'!$S:$S,'DIÁRIO (2)'!$B14) -> 0 | ... T14: =SUMIFS('CONTAS A PAGAR SIMULAÇÃO'!$N:$N,'CONTAS A PAGAR SIMULAÇÃO'!$K:$K,'DIÁRIO (2)'!T$3,'CONTAS A PAGAR SIMULAÇÃO'!$S:$S,'DIÁRIO (2)'!$B14) -> 0 | U14: =SUM(C14:T14) -> 340
B15: Vale Transporte | C15: =SUMIFS('CONTAS A PAGAR SIMULAÇÃO'!$N:$N,'CONTAS A PAGAR SIMULAÇÃO'!$K:$K,'DIÁRIO (2)'!C$3,'CONTAS A PAGAR SIMULAÇÃO'!$S:$S,'DIÁRIO (2)'!$B15) -> 0 | D15: =SUMIFS('CONTAS A PAGAR SIMULAÇÃO'!$N:$N,'CONTAS A PAGAR SIMULAÇÃO'!$K:$K,'DIÁRIO (2)'!D$3,'CONTAS A PAGAR SIMULAÇÃO'!$S:$S,'DIÁRIO (2)'!$B15) -> 0 | E15: =SUMIFS('CONTAS A PAGAR SIMULAÇÃO'!$N:$N,'CONTAS A PAGAR SIMULAÇÃO'!$K:$K,'DIÁRIO (2)'!E$3,'CONTAS A PAGAR SIMULAÇÃO'!$S:$S,'DIÁRIO (2)'!$B15) -> 0 | F15: =SUMIFS('CONTAS A PAGAR SIMULAÇÃO'!$N:$N,'CONTAS A PAGAR SIMULAÇÃO'!$K:$K,'DIÁRIO (2)'!F$3,'CONTAS A PAGAR SIMULAÇÃO'!$S:$S,'DIÁRIO (2)'!$B15) -> 0 | G15: =SUMIFS('CONTAS A PAGAR SIMULAÇÃO'!$N:$N,'CONTAS A PAGAR SIMULAÇÃO'!$K:$K,'DIÁRIO (2)'!G$3,'CONTAS A PAGAR SIMULAÇÃO'!$S:$S,'DIÁRIO (2)'!$B15) -> 0 | H15: =SUMIFS('CONTAS A PAGAR SIMULAÇÃO'!$N:$N,'CONTAS A PAGAR SIMULAÇÃO'!$K:$K,'DIÁRIO (2)'!H$3,'CONTAS A PAGAR SIMULAÇÃO'!$S:$S,'DIÁRIO (2)'!$B15) -> 0 | I15: =SUMIFS('CONTAS A PAGAR SIMULAÇÃO'!$N:$N,'CONTAS A PAGAR SIMULAÇÃO'!$K:$K,'DIÁRIO (2)'!I$3,'CONTAS A PAGAR SIMULAÇÃO'!$S:$S,'DIÁRIO (2)'!$B15) -> 0 | J15: =SUMIFS('CONTAS A PAGAR SIMULAÇÃO'!$N:$N,'CONTAS A PAGAR SIMULAÇÃO'!$K:$K,'DIÁRIO (2)'!J$3,'CONTAS A PAGAR SIMULAÇÃO'!$S:$S,'DIÁRIO (2)'!$B15) -> 0 | ... T15: =SUMIFS('CONTAS A PAGAR SIMULAÇÃO'!$N:$N,'CONTAS A PAGAR SIMULAÇÃO'!$K:$K,'DIÁRIO (2)'!T$3,'CONTAS A PAGAR SIMULAÇÃO'!$S:$S,'DIÁRIO (2)'!$B15) -> 0 | U15: =SUM(C15:T15) -> 0
... B65: Fgts, Gps e Pis | C65: =SUMIFS('CONTAS A PAGAR SIMULAÇÃO'!$N:$N,'CONTAS A PAGAR SIMULAÇÃO'!$K:$K,'DIÁRIO (2)'!C$3,'CONTAS A PAGAR SIMULAÇÃO'!$S:$S,'DIÁRIO (2)'!$B65) -> 0 | D65: =SUMIFS('CONTAS A PAGAR SIMULAÇÃO'!$N:$N,'CONTAS A PAGAR SIMULAÇÃO'!$K:$K,'DIÁRIO (2)'!D$3,'CONTAS A PAGAR SIMULAÇÃO'!$S:$S,'DIÁRIO (2)'!$B65) -> 0 | E65: =SUMIFS('CONTAS A PAGAR SIMULAÇÃO'!$N:$N,'CONTAS A PAGAR SIMULAÇÃO'!$K:$K,'DIÁRIO (2)'!E$3,'CONTAS A PAGAR SIMULAÇÃO'!$S:$S,'DIÁRIO (2)'!$B65) -> 0 | F65: =SUMIFS('CONTAS A PAGAR SIMULAÇÃO'!$N:$N,'CONTAS A PAGAR SIMULAÇÃO'!$K:$K,'DIÁRIO (2)'!F$3,'CONTAS A PAGAR SIMULAÇÃO'!$S:$S,'DIÁRIO (2)'!$B65) -> 0 | G65: =SUMIFS('CONTAS A PAGAR SIMULAÇÃO'!$N:$N,'CONTAS A PAGAR SIMULAÇÃO'!$K:$K,'DIÁRIO (2)'!G$3,'CONTAS A PAGAR SIMULAÇÃO'!$S:$S,'DIÁRIO (2)'!$B65) -> 0 | H65: =SUMIFS('CONTAS A PAGAR SIMULAÇÃO'!$N:$N,'CONTAS A PAGAR SIMULAÇÃO'!$K:$K,'DIÁRIO (2)'!H$3,'CONTAS A PAGAR SIMULAÇÃO'!$S:$S,'DIÁRIO (2)'!$B65) -> 0 | I65: =SUMIFS('CONTAS A PAGAR SIMULAÇÃO'!$N:$N,'CONTAS A PAGAR SIMULAÇÃO'!$K:$K,'DIÁRIO (2)'!I$3,'CONTAS A PAGAR SIMULAÇÃO'!$S:$S,'DIÁRIO (2)'!$B65) -> 3989.34 | J65: =SUMIFS('CONTAS A PAGAR SIMULAÇÃO'!$N:$N,'CONTAS A PAGAR SIMULAÇÃO'!$K:$K,'DIÁRIO (2)'!J$3,'CONTAS A PAGAR SIMULAÇÃO'!$S:$S,'DIÁRIO (2)'!$B65) -> 0 | ... T65: =SUMIFS('CONTAS A PAGAR SIMULAÇÃO'!$N:$N,'CONTAS A PAGAR SIMULAÇÃO'!$K:$K,'DIÁRIO (2)'!T$3,'CONTAS A PAGAR SIMULAÇÃO'!$S:$S,'DIÁRIO (2)'!$B65) -> 0 | U65: =SUM(C65:T65) -> 3989.34

Sheet POR FORNECEDOR
A1: PESSOA | B1: JULHO | C1: AGOSTO | D1: SETEMBRO | E1: OUTUBRO | F1: NOVEMBRO | G1: DEZEMBRO | H1: TOTAL
A2: ALVO TEXTIL | B2: =SUMIFS('CONTAS A PAGAR'!$N:$N,'CONTAS A PAGAR'!$H:$H,'POR FORNECEDOR'!$A2,'CONTAS A PAGAR'!$Z:$Z,'POR FORNECEDOR'!B$1) -> 0 | C2: =SUMIFS('CONTAS A PAGAR'!$N:$N,'CONTAS A PAGAR'!$H:$H,'POR FORNECEDOR'!$A2,'CONTAS A PAGAR'!$Z:$Z,'POR FORNECEDOR'!C$1) -> 0 | D2: =SUMIFS('CONTAS A PAGAR'!$N:$N,'CONTAS A PAGAR'!$H:$H,'POR FORNECEDOR'!$A2,'CONTAS A PAGAR'!$Z:$Z,'POR FORNECEDOR'!D$1) -> 0 | E2: =SUMIFS('CONTAS A PAGAR'!$N:$N,'CONTAS A PAGAR'!$H:$H,'POR FORNECEDOR'!$A2,'CONTAS A PAGAR'!$Z:$Z,'POR FORNECEDOR'!E$1) -> 0 | F2: =SUMIFS('CONTAS A PAGAR'!$N:$N,'CONTAS A PAGAR'!$H:$H,'POR FORNECEDOR'!$A2,'CONTAS A PAGAR'!$Z:$Z,'POR FORNECEDOR'!F$1) -> 0 | G2: =SUMIFS('CONTAS A PAGAR'!$N:$N,'CONTAS A PAGAR'!$H:$H,'POR FORNECEDOR'!$A2,'CONTAS A PAGAR'!$Z:$Z,'POR FORNECEDOR'!G$1) -> 0 | H2: =SUM(E2:G2) -> 0
A3: LÍDER TECIDOS | B3: =SUMIFS('CONTAS A PAGAR'!$N:$N,'CONTAS A PAGAR'!$H:$H,'POR FORNECEDOR'!$A3,'CONTAS A PAGAR'!$Z:$Z,'POR FORNECEDOR'!B$1) -> 0 | C3: =SUMIFS('CONTAS A PAGAR'!$N:$N,'CONTAS A PAGAR'!$H:$H,'POR FORNECEDOR'!$A3,'CONTAS A PAGAR'!$Z:$Z,'POR FORNECEDOR'!C$1) -> 0 | D3: =SUMIFS('CONTAS A PAGAR'!$N:$N,'CONTAS A PAGAR'!$H:$H,'POR FORNECEDOR'!$A3,'CONTAS A PAGAR'!$Z:$Z,'POR FORNECEDOR'!D$1) -> 0 | E3: =SUMIFS('CONTAS A PAGAR'!$N:$N,'CONTAS A PAGAR'!$H:$H,'POR FORNECEDOR'!$A3,'CONTAS A PAGAR'!$Z:$Z,'POR FORNECEDOR'!E$1) -> 0 | F3: =SUMIFS('CONTAS A PAGAR'!$N:$N,'CONTAS A PAGAR'!$H:$H,'POR FORNECEDOR'!$A3,'CONTAS A PAGAR'!$Z:$Z,'POR FORNECEDOR'!F$1) -> 0 | G3: =SUMIFS('CONTAS A PAGAR'!$N:$N,'CONTAS A PAGAR'!$H:$H,'POR FORNECEDOR'!$A3,'CONTAS A PAGAR'!$Z:$Z,'POR FORNECEDOR'!G$1) -> 0 | H3: =SUM(E3:G3) -> 0
A4: VICUNHA TEXTIL S/A. | B4: =SUMIFS('CONTAS A PAGAR'!$N:$N,'CONTAS A PAGAR'!$H:$H,'POR FORNECEDOR'!$A4,'CONTAS A PAGAR'!$Z:$Z,'POR FORNECEDOR'!B$1) -> 0 | C4: =SUMIFS('CONTAS A PAGAR'!$N:$N,'CONTAS A PAGAR'!$H:$H,'POR FORNECEDOR'!$A4,'CONTAS A PAGAR'!$Z:$Z,'POR FORNECEDOR'!C$1) -> 0 | D4: =SUMIFS('CONTAS A PAGAR'!$N:$N,'CONTAS A PAGAR'!$H:$H,'POR FORNECEDOR'!$A4,'CONTAS A PAGAR'!$Z:$Z,'POR FORNECEDOR'!D$1) -> 0 | E4: =SUMIFS('CONTAS A PAGAR'!$N:$N,'CONTAS A PAGAR'!$H:$H,'POR FORNECEDOR'!$A4,'CONTAS A PAGAR'!$Z:$Z,'POR FORNECEDOR'!E$1) -> 0 | F4: =SUMIFS('CONTAS A PAGAR'!$N:$N,'CONTAS A PAGAR'!$H:$H,'POR FORNECEDOR'!$A4,'CONTAS A PAGAR'!$Z:$Z,'POR FORNECEDOR'!F$1) -> 0 | G4: =SUMIFS('CONTAS A PAGAR'!$N:$N,'CONTAS A PAGAR'!$H:$H,'POR FORNECEDOR'!$A4,'CONTAS A PAGAR'!$Z:$Z,'POR FORNECEDOR'!G$1) -> 0 | H4: =SUM(E4:G4) -> 0
A5: EXCIM IMPORTAÇÃO E EXPORTAÇÃO LTDA | B5: =SUMIFS('CONTAS A PAGAR'!$N:$N,'CONTAS A PAGAR'!$H:$H,'POR FORNECEDOR'!$A5,'CONTAS A PAGAR'!$Z:$Z,'POR FORNECEDOR'!B$1) -> 0 | C5: =SUMIFS('CONTAS A PAGAR'!$N:$N,'CONTAS A PAGAR'!$H:$H,'POR FORNECEDOR'!$A5,'CONTAS A PAGAR'!$Z:$Z,'POR FORNECEDOR'!C$1) -> 0 | D5: =SUMIFS('CONTAS A PAGAR'!$N:$N,'CONTAS A PAGAR'!$H:$H,'POR FORNECEDOR'!$A5,'CONTAS A PAGAR'!$Z:$Z,'POR FORNECEDOR'!D$1) -> 0 | E5: =SUMIFS('CONTAS A PAGAR'!$N:$N,'CONTAS A PAGAR'!$H:$H,'POR FORNECEDOR'!$A5,'CONTAS A PAGAR'!$Z:$Z,'POR FORNECEDOR'!E$1) -> 0 | F5: =SUMIFS('CONTAS A PAGAR'!$N:$N,'CONTAS A PAGAR'!$H:$H,'POR FORNECEDOR'!$A5,'CONTAS A PAGAR'!$Z:$Z,'POR FORNECEDOR'!F$1) -> 0 | G5: =SUMIFS('CONTAS A PAGAR'!$N:$N,'CONTAS A PAGAR'!$H:$H,'POR FORNECEDOR'!$A5,'CONTAS A PAGAR'!$Z:$Z,'POR FORNECEDOR'!G$1) -> 0 | H5: =SUM(E5:G5) -> 0
A6: SANTISTA TEXTIL | B6: =SUMIFS('CONTAS A PAGAR'!$N:$N,'CONTAS A PAGAR'!$H:$H,'POR FORNECEDOR'!$A6,'CONTAS A PAGAR'!$Z:$Z,'POR FORNECEDOR'!B$1) -> 0 | C6: =SUMIFS('CONTAS A PAGAR'!$N:$N,'CONTAS A PAGAR'!$H:$H,'POR FORNECEDOR'!$A6,'CONTAS A PAGAR'!$Z:$Z,'POR FORNECEDOR'!C$1) -> 0 | D6: =SUMIFS('CONTAS A PAGAR'!$N:$N,'CONTAS A PAGAR'!$H:$H,'POR FORNECEDOR'!$A6,'CONTAS A PAGAR'!$Z:$Z,'POR FORNECEDOR'!D$1) -> 0 | E6: =SUMIFS('CONTAS A PAGAR'!$N:$N,'CONTAS A PAGAR'!$H:$H,'POR FORNECEDOR'!$A6,'CONTAS A PAGAR'!$Z:$Z,'POR FORNECEDOR'!E$1) -> 0 | F6: =SUMIFS('CONTAS A PAGAR'!$N:$N,'CONTAS A PAGAR'!$H:$H,'POR FORNECEDOR'!$A6,'CONTAS A PAGAR'!$Z:$Z,'POR FORNECEDOR'!F$1) -> 0 | G6: =SUMIFS('CONTAS A PAGAR'!$N:$N,'CONTAS A PAGAR'!$H:$H,'POR FORNECEDOR'!$A6,'CONTAS A PAGAR'!$Z:$Z,'POR FORNECEDOR'!G$1) -> 0 | H6: =SUM(E6:G6) -> 0
A7: CEDRO TEXTIL | B7: =SUMIFS('CONTAS A PAGAR'!$N:$N,'CONTAS A PAGAR'!$H:$H,'POR FORNECEDOR'!$A7,'CONTAS A PAGAR'!$Z:$Z,'POR FORNECEDOR'!B$1) -> 0 | C7: =SUMIFS('CONTAS A PAGAR'!$N:$N,'CONTAS A PAGAR'!$H:$H,'POR FORNECEDOR'!$A7,'CONTAS A PAGAR'!$Z:$Z,'POR FORNECEDOR'!C$1) -> 0 | D7: =SUMIFS('CONTAS A PAGAR'!$N:$N,'CONTAS A PAGAR'!$H:$H,'POR FORNECEDOR'!$A7,'CONTAS A PAGAR'!$Z:$Z,'POR FORNECEDOR'!D$1) -> 0 | E7: =SUMIFS('CONTAS A PAGAR'!$N:$N,'CONTAS A PAGAR'!$H:$H,'POR FORNECEDOR'!$A7,'CONTAS A PAGAR'!$Z:$Z,'POR FORNECEDOR'!E$1) -> 0 | F7: =SUMIFS('CONTAS A PAGAR'!$N:$N,'CONTAS A PAGAR'!$H:$H,'POR FORNECEDOR'!$A7,'CONTAS A PAGAR'!$Z:$Z,'POR FORNECEDOR'!F$1) -> 0 | G7: =SUMIFS('CONTAS A PAGAR'!$N:$N,'CONTAS A PAGAR'!$H:$H,'POR FORNECEDOR'!$A7,'CONTAS A PAGAR'!$Z:$Z,'POR FORNECEDOR'!G$1) -> 0 | H7: 473000 | I7: AMILTON
A8: JOAO - CAPITAL DE GIRO | B8: =SUMIFS('CONTAS A PAGAR'!$N:$N,'CONTAS A PAGAR'!$H:$H,'POR FORNECEDOR'!$A8,'CONTAS A PAGAR'!$Z:$Z,'POR FORNECEDOR'!B$1) -> 0 | C8: =SUMIFS('CONTAS A PAGAR'!$N:$N,'CONTAS A PAGAR'!$H:$H,'POR FORNECEDOR'!$A8,'CONTAS A PAGAR'!$Z:$Z,'POR FORNECEDOR'!C$1) -> 0 | D8: =SUMIFS('CONTAS A PAGAR'!$N:$N,'CONTAS A PAGAR'!$H:$H,'POR FORNECEDOR'!$A8,'CONTAS A PAGAR'!$Z:$Z,'POR FORNECEDOR'!D$1) -> 0 | E8: =SUMIFS('CONTAS A PAGAR'!$N:$N,'CONTAS A PAGAR'!$H:$H,'POR FORNECEDOR'!$A8,'CONTAS A PAGAR'!$Z:$Z,'POR FORNECEDOR'!E$1) -> 0 | F8: =SUMIFS('CONTAS A PAGAR'!$N:$N,'CONTAS A PAGAR'!$H:$H,'POR FORNECEDOR'!$A8,'CONTAS A PAGAR'!$Z:$Z,'POR FORNECEDOR'!F$1) -> 0 | G8: =SUMIFS('CONTAS A PAGAR'!$N:$N,'CONTAS A PAGAR'!$H:$H,'POR FORNECEDOR'!$A8,'CONTAS A PAGAR'!$Z:$Z,'POR FORNECEDOR'!G$1) -> 0 | H8: =SUM(E8:G8) -> 0
A9: TEXTIL CANATIBA LTDA | B9: =SUMIFS('CONTAS A PAGAR'!$N:$N,'CONTAS A PAGAR'!$H:$H,'POR FORNECEDOR'!$A9,'CONTAS A PAGAR'!$Z:$Z,'POR FORNECEDOR'!B$1) -> 0 | C9: =SUMIFS('CONTAS A PAGAR'!$N:$N,'CONTAS A PAGAR'!$H:$H,'POR FORNECEDOR'!$A9,'CONTAS A PAGAR'!$Z:$Z,'POR FORNECEDOR'!C$1) -> 0 | D9: =SUMIFS('CONTAS A PAGAR'!$N:$N,'CONTAS A PAGAR'!$H:$H,'POR FORNECEDOR'!$A9,'CONTAS A PAGAR'!$Z:$Z,'POR FORNECEDOR'!D$1) -> 0 | E9: =SUMIFS('CONTAS A PAGAR'!$N:$N,'CONTAS A PAGAR'!$H:$H,'POR FORNECEDOR'!$A9,'CONTAS A PAGAR'!$Z:$Z,'POR FORNECEDOR'!E$1) -> 0 | F9: =SUMIFS('CONTAS A PAGAR'!$N:$N,'CONTAS A PAGAR'!$H:$H,'POR FORNECEDOR'!$A9,'CONTAS A PAGAR'!$Z:$Z,'POR FORNECEDOR'!F$1) -> 0 | G9: =SUMIFS('CONTAS A PAGAR'!$N:$N,'CONTAS A PAGAR'!$H:$H,'POR FORNECEDOR'!$A9,'CONTAS A PAGAR'!$Z:$Z,'POR FORNECEDOR'!G$1) -> 0 | H9: =SUM(E9:G9) -> 0
A10: SERGITEX TEXTIL RANDAL | B10: =SUMIFS('CONTAS A PAGAR'!$N:$N,'CONTAS A PAGAR'!$H:$H,'POR FORNECEDOR'!$A10,'CONTAS A PAGAR'!$Z:$Z,'POR FORNECEDOR'!B$1) -> 0 | C10: =SUMIFS('CONTAS A PAGAR'!$N:$N,'CONTAS A PAGAR'!$H:$H,'POR FORNECEDOR'!$A10,'CONTAS A PAGAR'!$Z:$Z,'POR FORNECEDOR'!C$1) -> 0 | D10: =SUMIFS('CONTAS A PAGAR'!$N:$N,'CONTAS A PAGAR'!$H:$H,'POR FORNECEDOR'!$A10,'CONTAS A PAGAR'!$Z:$Z,'POR FORNECEDOR'!D$1) -> 0 | E10: =SUMIFS('CONTAS A PAGAR'!$N:$N,'CONTAS A PAGAR'!$H:$H,'POR FORNECEDOR'!$A10,'CONTAS A PAGAR'!$Z:$Z,'POR FORNECEDOR'!E$1) -> 0 | F10: =SUMIFS('CONTAS A PAGAR'!$N:$N,'CONTAS A PAGAR'!$H:$H,'POR FORNECEDOR'!$A10,'CONTAS A PAGAR'!$Z:$Z,'POR FORNECEDOR'!F$1) -> 0 | G10: =SUMIFS('CONTAS A PAGAR'!$N:$N,'CONTAS A PAGAR'!$H:$H,'POR FORNECEDOR'!$A10,'CONTAS A PAGAR'!$Z:$Z,'POR FORNECEDOR'!G$1) -> 0 | H10: =SUM(E10:G10) -> 0
A11: CIA FIACAO E TECIDOS CEDRO E CACHOE | B11: =SUMIFS('CONTAS A PAGAR'!$N:$N,'CONTAS A PAGAR'!$H:$H,'POR FORNECEDOR'!$A11,'CONTAS A PAGAR'!$Z:$Z,'POR FORNECEDOR'!B$1) -> 0 | C11: =SUMIFS('CONTAS A PAGAR'!$N:$N,'CONTAS A PAGAR'!$H:$H,'POR FORNECEDOR'!$A11,'CONTAS A PAGAR'!$Z:$Z,'POR FORNECEDOR'!C$1) -> 0 | D11: =SUMIFS('CONTAS A PAGAR'!$N:$N,'CONTAS A PAGAR'!$H:$H,'POR FORNECEDOR'!$A11,'CONTAS A PAGAR'!$Z:$Z,'POR FORNECEDOR'!D$1) -> 0 | E11: =SUMIFS('CONTAS A PAGAR'!$N:$N,'CONTAS A PAGAR'!$H:$H,'POR FORNECEDOR'!$A11,'CONTAS A PAGAR'!$Z:$Z,'POR FORNECEDOR'!E$1) -> 0 | F11: =SUMIFS('CONTAS A PAGAR'!$N:$N,'CONTAS A PAGAR'!$H:$H,'POR FORNECEDOR'!$A11,'CONTAS A PAGAR'!$Z:$Z,'POR FORNECEDOR'!F$1) -> 0 | G11: =SUMIFS('CONTAS A PAGAR'!$N:$N,'CONTAS A PAGAR'!$H:$H,'POR FORNECEDOR'!$A11,'CONTAS A PAGAR'!$Z:$Z,'POR FORNECEDOR'!G$1) -> 0 | H11: =SUM(E11:G11) -> 0
A12: TEXTIL FAVERO LTDA | B12: =SUMIFS('CONTAS A PAGAR'!$N:$N,'CONTAS A PAGAR'!$H:$H,'POR FORNECEDOR'!$A12,'CONTAS A PAGAR'!$Z:$Z,'POR FORNECEDOR'!B$1) -> 0 | C12: =SUMIFS('CONTAS A PAGAR'!$N:$N,'CONTAS A PAGAR'!$H:$H,'POR FORNECEDOR'!$A12,'CONTAS A PAGAR'!$Z:$Z,'POR FORNECEDOR'!C$1) -> 0 | D12: =SUMIFS('CONTAS A PAGAR'!$N:$N,'CONTAS A PAGAR'!$H:$H,'POR FORNECEDOR'!$A12,'CONTAS A PAGAR'!$Z:$Z,'POR FORNECEDOR'!D$1) -> 0 | E12: =SUMIFS('CONTAS A PAGAR'!$N:$N,'CONTAS A PAGAR'!$H:$H,'POR FORNECEDOR'!$A12,'CONTAS A PAGAR'!$Z:$Z,'POR FORNECEDOR'!E$1) -> 0 | F12: =SUMIFS('CONTAS A PAGAR'!$N:$N,'CONTAS A PAGAR'!$H:$H,'POR FORNECEDOR'!$A12,'CONTAS A PAGAR'!$Z:$Z,'POR FORNECEDOR'!F$1) -> 0 | G12: =SUMIFS('CONTAS A PAGAR'!$N:$N,'CONTAS A PAGAR'!$H:$H,'POR FORNECEDOR'!$A12,'CONTAS A PAGAR'!$Z:$Z,'POR FORNECEDOR'!G$1) -> 0 | H12: =SUM(E12:G12) -> 0
A13: TEXTIL FAVERO | B13: =SUMIFS('CONTAS A PAGAR'!$N:$N,'CONTAS A PAGAR'!$H:$H,'POR FORNECEDOR'!$A13,'CONTAS A PAGAR'!$Z:$Z,'POR FORNECEDOR'!B$1) -> 0 | C13: =SUMIFS('CONTAS A PAGAR'!$N:$N,'CONTAS A PAGAR'!$H:$H,'POR FORNECEDOR'!$A13,'CONTAS A PAGAR'!$Z:$Z,'POR FORNECEDOR'!C$1) -> 0 | D13: =SUMIFS('CONTAS A PAGAR'!$N:$N,'CONTAS A PAGAR'!$H:$H,'POR FORNECEDOR'!$A13,'CONTAS A PAGAR'!$Z:$Z,'POR FORNECEDOR'!D$1) -> 0 | E13: =SUMIFS('CONTAS A PAGAR'!$N:$N,'CONTAS A PAGAR'!$H:$H,'POR FORNECEDOR'!$A13,'CONTAS A PAGAR'!$Z:$Z,'POR FORNECEDOR'!E$1) -> 0 | F13: =SUMIFS('CONTAS A PAGAR'!$N:$N,'CONTAS A PAGAR'!$H:$H,'POR FORNECEDOR'!$A13,'CONTAS A PAGAR'!$Z:$Z,'POR FORNECEDOR'!F$1) -> 0 | G13: =SUMIFS('CONTAS A PAGAR'!$N:$N,'CONTAS A PAGAR'!$H:$H,'POR FORNECEDOR'!$A13,'CONTAS A PAGAR'!$Z:$Z,'POR FORNECEDOR'!G$1) -> 0 | H13: =SUM(E13:G13) -> 0
E22: rossi.caetano@cedro.ind.br

Sheet CONTAS A PAGAR SIMULAÇÃO
A1: EMP. CADASTRO | B1: EMP.REFERENTE | C1: ID | D1: ID.ITEM | E1: DOCUMENTO | F1: COD. PESSOA | G1: CNPJ | H1: PESSOA | I1: DT. CAD. | J1: DT. EMISSÃO | K1: DT. VENC. | L1: DT. BAIXA | M1: FORMA PAGTO. | N1: VALOR | O1: VALOR PAGO | P1: SIT | Q1: ID.PL.CONTAS | R1: COD. PL CONTAS | S1: PLANO DE CONTAS | T1: CENTRO DE CUSTO | U1: COD.CONTA | V1: CONTA | W1: ORIGEM CAD.PESSOAS | X1: OBS.: | Y1: MÊS | Z1: MÊS TEXTO
A2: 1154 | B2: 1154 | C2: 985 | D2: 6 | E2: 002822-6/_x000D_ 6 | F2: 1979 | H2: ALVO TEXTIL | I2: 45616 | J2: 45616 | K2: 45836 | L2: 45839 | M2: CHEQUE - EMPRESA | N2: 4800 | O2: 4800 | P2: B | Q2: 26 | R2: 02.01.09 | S2: Tecidos | T2: CODI.COM JEANS | V2: ITAU ALV | W2: Sem Origem | Y2: =IF(L2="",K2,L2) -> 45839 | Z2: =TEXT(Y2,"MMMM") -> julho
A3: 1154 | B3: 1154 | C3: 986 | D3: 1 | E3: 002823-1/_x000D_ 6 | F3: 1979 | H3: ALVO TEXTIL | I3: 45616 | J3: 45616 | K3: 45838 | L3: 45839 | M3: CHEQUE - EMPRESA | N3: 4800 | O3: 4800 | P3: B | Q3: 26 | R3: 02.01.09 | S3: Tecidos | T3: CODI.COM JEANS | V3: ITAU ALV | W3: Sem Origem | Y3: =IF(L3="",K3,L3) -> 45839 | Z3: =TEXT(Y3,"MMMM") -> julho
A4: 1154 | B4: 1154 | C4: 1189 | D4: 6 | E4: 002842-6/_x000D_ 6 | F4: 1985 | H4: LÍDER TECIDOS | I4: 45653 | J4: 45653 | K4: 45838 | L4: 45839 | M4: CHEQUE - EMPRESA | N4: 4880 | O4: 4880 | P4: B | Q4: 26 | R4: 02.01.09 | S4: Tecidos | T4: CODI.COM JEANS | V4: ITAU ALV | W4: Sem Origem | Y4: =IF(L4="",K4,L4) -> 45839 | Z4: =TEXT(Y4,"MMMM") -> julho
A5: 1154 | B5: 1154 | C5: 1645 | D5: 1 | E5: 002892-4/_x000D_ 42 | F5: 1985 | H5: LÍDER TECIDOS | I5: 45733 | J5: 45733 | K5: 45838 | L5: 45839 | M5: CHEQUE - EMPRESA | N5: 4920 | O5: 4920 | P5: B | Q5: 26 | R5: 02.01.09 | S5: Tecidos | T5: DESPESAS FONECEDORES | V5: ITAU ALV | W5: Sem Origem | Y5: =IF(L5="",K5,L5) -> 45839 | Z5: =TEXT(Y5,"MMMM") -> julho
A6: 1154 | B6: 1154 | C6: 1963 | D6: 1 | E6: 002880-2/_x000D_ 3 | F6: 2182 | H6: BLESSED LAVANDERIA | I6: 45757 | J6: 45757 | K6: 45838 | L6: 45839 | M6: CHEQUE - EMPRESA | N6: 4200 | O6: 4200 | P6: B | Q6: 28 | R6: 02.01.11 | S6: Lavanderia | T6: DESPESAS FONECEDORES | V6: ITAU ALV | W6: Sem Origem | Y6: =IF(L6="",K6,L6) -> 45839 | Z6: =TEXT(Y6,"MMMM") -> julho
A7: 1154 | B7: 1154 | C7: 2037 | D7: 2 | E7: 0722555-2_x000D_ /3 | F7: 1526 | G7: 07.332.190/0007-89 | H7: VICUNHA TEXTIL S/A. | I7: 45769 | J7: 45769 | K7: 45839 | L7: 45839 | M7: BOLETO BANCÁRIO | N7: 2487.92 | O7: 2487.92 | P7: B | Q7: 26 | R7: 02.01.09 | S7: Tecidos | T7: DESPESAS FONECEDORES | V7: ITAU ALV | W7: Sem Origem | X7: Cyros Tecidos Sarja | Y7: =IF(L7="",K7,L7) -> 45839 | Z7: =TEXT(Y7,"MMMM") -> julho
A8: 1154 | B8: 1154 | C8: 2198 | D8: 1 | E8: 2T-OP271_x000D_ -1/1 | F8: 1957 | H8: ROGERIO - TRAVETE | I8: 45782 | J8: 45782 | K8: 45843 | L8: 45839 | M8: PIX ITAU ALV | N8: 119 | O8: 119 | P8: B | Q8: 27 | R8: 02.01.10 | S8: Travete | T8: DESPESAS FONECEDORES | V8: ITAU ALV | W8: Sem Origem | X8: Pagamento de Ordens de Serviço:895, | Y8: =IF(L8="",K8,L8) -> 45839 | Z8: =TEXT(Y8,"MMMM") -> julho
A9: 1154 | B9: 1154 | C9: 2238 | D9: 1 | E9: 2T-OP274_x000D_ -1/1 | F9: 1957 | H9: ROGERIO - TRAVETE | I9: 45783 | J9: 45783 | K9: 45843 | L9: 45839 | M9: PIX ITAU ALV | N9: 195 | O9: 195 | P9: B | Q9: 27 | R9: 02.01.10 | S9: Travete | T9: DESPESAS FONECEDORES | V9: ITAU ALV | W9: Sem Origem | X9: Pagamento de Ordens de Serviço:904, | Y9: =IF(L9="",K9,L9) -> 45839 | Z9: =TEXT(Y9,"MMMM") -> julho
A10: 1154 | B10: 1154 | C10: 2501 | D10: 1 | E10: 2T-OP268_x000D_ -1/1 | F10: 2142 | H10: ADRIANO-FACÇÃO | I10: 45807 | J10: 45807 | K10: 45810 | L10: 45839 | M10: PIX ITAU ALV | N10: 1963.5 | O10: 1963.5 | P10: B | Q10: 21 | R10: 02.01.04 | S10: Facção | T10: DESPESAS FONECEDORES | V10: ITAU ALV | W10: Sem Origem | Y10: =IF(L10="",K10,L10) -> 45839 | Z10: =TEXT(Y10,"MMMM") -> julho
A11: 1154 | B11: 1154 | C11: 2502 | D11: 1 | E11: 2T-OP283_x000D_ -1/1 | F11: 1956 | H11: EMERSON - FACÇÃO | I11: 45807 | J11: 45807 | K11: 45810 | L11: 45839 | M11: PIX ITAU ALV | N11: 2310 | O11: 2310 | P11: B | Q11: 21 | R11: 02.01.04 | S11: Facção | T11: DESPESAS FONECEDORES | V11: ITAU ALV | W11: Sem Origem | Y11: =IF(L11="",K11,L11) -> 45839 | Z11: =TEXT(Y11,"MMMM") -> julho
A12: 1154 | B12: 1154 | C12: 2652 | D12: 1 | E12: 2T-OP324_x000D_ -1/1 | F12: 2531 | H12: JUNIOR FACÇÃO | I12: 45824 | J12: 45824 | K12: 45824 | L12: 45839 | M12: PIX ITAU ALV | N12: 1680 | O12: 1680 | P12: B | Q12: 21 | R12: 02.01.04 | S12: Facção | T12: DESPESAS FONECEDORES | V12: ITAU ALV | W12: Sem Origem | X12: Pagamento de Ordens de Serviço:1056, | Y12: =IF(L12="",K12,L12) -> 45839 | Z12: =TEXT(Y12,"MMMM") -> julho
A13: 1154 | B13: 1154 | C13: 2691 | D13: 1 | E13: 2T-OP331_x000D_ -1/1 | F13: 1954 | H13: HERON - FACÇÃO | I13: 45825 | J13: 45825 | K13: 45831 | L13: 45839 | M13: PIX ITAU ALV | N13: 2070 | O13: 2070 | P13: B | Q13: 21 | R13: 02.01.04 | S13: Facção | T13: DESPESAS FONECEDORES | V13: ITAU ALV | W13: Sem Origem | X13: Pagamento de Ordens de Serviço:1077, | Y13: =IF(L13="",K13,L13) -> 45839 | Z13: =TEXT(Y13,"MMMM") -> julho
A14: 1154 | B14: 1154 | C14: 2694 | D14: 1 | E14: 2T-OP332_x000D_ -1/1 | F14: 1954 | H14: HERON - FACÇÃO | I14: 45825 | J14: 45825 | K14: 45838 | L14: 45839 | M14: PIX ITAU ALV | N14: 1771 | O14: 1771 | P14: B | Q14: 21 | R14: 02.01.04 | S14: Facção | T14: DESPESAS FONECEDORES | V14: ITAU ALV | W14: Sem Origem | X14: Pagamento de Ordens de Serviço:1080, | Y14: =IF(L14="",K14,L14) -> 45839 | Z14: =TEXT(Y14,"MMMM") -> julho
A15: 1154 | B15: 1154 | C15: 2697 | D15: 1 | E15: 2T-OP333_x000D_ -1/1 | F15: 2142 | H15: ADRIANO-FACÇÃO | I15: 45825 | J15: 45825 | K15: 45831 | L15: 45839 | M15: PIX ITAU ALV | N15: 2116 | O15: 2116 | P15: B | Q15: 21 | R15: 02.01.04 | S15: Facção | T15: DESPESAS FONECEDORES | V15: ITAU ALV | W15: Sem Origem | X15: Pagamento de Ordens de Serviço:1083, | Y15: =IF(L15="",K15,L15) -> 45839 | Z15: =TEXT(Y15,"MMMM") -> julho
A16: 1154 | B16: 1154 | C16: 2704 | D16: 1 | E16: 2T-OP332_x000D_ -1/1 | F16: 2569 | H16: DIVINO-ACABAMENTO | I16: 45826 | J16: 45826 | K16: 45843 | L16: 45840 | M16: PIX ITAU ALV | N16: 323.4 | O16: 323.4 | P16: B | Q16: 18 | R16: 02.01.01 | S16: Acabamento Externo | T16: DESPESAS FONECEDORES | V16: ITAU ALV | W16: Sem Origem | X16: Pagamento de Ordens de Serviço:1086, | Y16: =IF(L16="",K16,L16) -> 45840 | Z16: =TEXT(Y16,"MMMM") -> julho
A17: 1154 | B17: 1154 | C17: 2605 | D17: 1 | E17: 2T-OP310_x000D_ -1/1 | F17: 2569 | H17: DIVINO-ACABAMENTO | I17: 45817 | J17: 45817 | K17: 45843 | L17: 45840 | M17: PIX ITAU ALV | N17: 655.2 | O17: 655.2 | P17: B | Q17: 18 | R17: 02.01.01 | S17: Acabamento Externo | T17: DESPESAS FONECEDORES | V17: ITAU ALV | W17: Sem Origem | X17: Pagamento de Ordens de Serviço:1041, | Y17: =IF(L17="",K17,L17) -> 45840 | Z17: =TEXT(Y17,"MMMM") -> julho
A18: 1154 | B18: 1154 | C18: 2606 | D18: 1 | E18: 2T-OP305_x000D_ -1/1 | F18: 2569 | H18: DIVINO-ACABAMENTO | I18: 45817 | J18: 45817 | K18: 45843 | L18: 45840 | M18: PIX ITAU ALV | N18: 420 | O18: 420 | P18: B | Q18: 18 | R18: 02.01.01 | S18: Acabamento Externo | T18: DESPESAS FONECEDORES | V18: ITAU ALV | W18: Sem Origem | X18: Pagamento de Ordens de Serviço:1042, | Y18: =IF(L18="",K18,L18) -> 45840 | Z18: =TEXT(Y18,"MMMM") -> julho
A19: 1154 | B19: 1154 | C19: 2607 | D19: 1 | E19: 2T-OP309_x000D_ -1/1 | F19: 2569 | H19: DIVINO-ACABAMENTO | I19: 45817 | J19: 45817 | K19: 45843 | L19: 45840 | M19: PIX ITAU ALV | N19: 252 | O19: 252 | P19: B | Q19: 18 | R19: 02.01.01 | S19: Acabamento Externo | T19: DESPESAS FONECEDORES | V19: ITAU ALV | W19: Sem Origem | X19: Pagamento de Ordens de Serviço:1043, | Y19: =IF(L19="",K19,L19) -> 45840 | Z19: =TEXT(Y19,"MMMM") -> julho
A20: 1154 | B20: 1154 | C20: 2575 | D20: 1 | E20: 2T-OP303_x000D_ -1/1 | F20: 2569 | H20: DIVINO-ACABAMENTO | I20: 45813 | J20: 45813 | K20: 45843 | L20: 45840 | M20: PIX ITAU ALV | N20: 882 | O20: 882 | P20: B | Q20: 18 | R20: 02.01.01 | S20: Acabamento Externo | T20: DESPESAS FONECEDORES | V20: ITAU ALV | W20: Sem Origem | X20: Pagamento de Ordens de Serviço:1040, | Y20: =IF(L20="",K20,L20) -> 45840 | Z20: =TEXT(Y20,"MMMM") -> julho
A21: 1154 | B21: 1154 | C21: 2615 | D21: 1 | E21: 2T-OP299_x000D_ -1/1 | F21: 2569 | H21: DIVINO-ACABAMENTO | I21: 45819 | J21: 45819 | K21: 45843 | L21: 45840 | M21: PIX ITAU ALV | N21: 428.4 | O21: 428.4 | P21: B | Q21: 18 | R21: 02.01.01 | S21: Acabamento Externo | T21: DESPESAS FONECEDORES | V21: ITAU ALV | W21: Sem Origem | X21: Pagamento de Ordens de Serviço:1044, | Y21: =IF(L21="",K21,L21) -> 45840 | Z21: =TEXT(Y21,"MMMM") -> julho
A22: 1154 | B22: 1154 | C22: 2807 | D22: 1 | E22: 45658 | F22: 1991 | H22: DESPESAS ESCRITORIO | I22: 45840 | J22: 45840 | K22: 45840 | L22: 45840 | M22: DINHEIRO | N22: 30 | O22: 30 | P22: B | Q22: 35 | R22: 02.02.05 | S22: Combustíveis | T22: CODI.COM JEANS | V22: ITAU ALV | W22: Sem Origem | X22: MOTO | Y22: =IF(L22="",K22,L22) -> 45840 | Z22: =TEXT(Y22,"MMMM") -> julho
A23: 1154 | B23: 1154 | C23: 2809 | D23: 1 | E23: 45658 | F23: 1991 | H23: DESPESAS ESCRITORIO | I23: 45840 | J23: 45840 | K23: 45840 | L23: 45840 | M23: DINHEIRO | N23: 860 | O23: 860 | P23: B | Q23: 42 | R23: 02.02.12 | S23: Manutenção de Máquinas e Peças | T23: CODI.COM JEANS | V23: ITAU ALV | W23: Sem Origem | X23: Manutenção Máquina de Corte | Y23: =IF(L23="",K23,L23) -> 45840 | Z23: =TEXT(Y23,"MMMM") -> julho
A24: 1154 | B24: 1154 | C24: 2729 | D24: 1 | E24: 2T-OP316_x000D_ -1/1 | F24: 2569 | H24: DIVINO-ACABAMENTO | I24: 45831 | J24: 45831 | K24: 45843 | L24: 45840 | M24: PIX ITAU ALV | N24: 378 | O24: 378 | P24: B | Q24: 18 | R24: 02.01.01 | S24: Acabamento Externo | T24: DESPESAS FONECEDORES | V24: ITAU ALV | W24: Sem Origem | X24: Pagamento de Ordens de Serviço:1103, | Y24: =IF(L24="",K24,L24) -> 45840 | Z24: =TEXT(Y24,"MMMM") -> julho
A25: 1154 | B25: 1154 | C25: 2730 | D25: 1 | E25: 2T-OP292_x000D_ -1/1 | F25: 2569 | H25: DIVINO-ACABAMENTO | I25: 45831 | J25: 45831 | K25: 45843 | L25: 45840 | M25: PIX ITAU ALV | N25: 417.9 | O25: 417.9 | P25: B | Q25: 18 | R25: 02.01.01 | S25: Acabamento Externo | T25: DESPESAS FONECEDORES | V25: ITAU ALV | W25: Sem Origem | X25: Pagamento de Ordens de Serviço:1102, | Y25: =IF(L25="",K25,L25) -> 45840 | Z25: =TEXT(Y25,"MMMM") -> julho
A26: 1154 | B26: 1154 | C26: 2731 | D26: 1 | E26: 2T-OP318_x000D_ -1/1 | F26: 2569 | H26: DIVINO-ACABAMENTO | I26: 45831 | J26: 45831 | K26: 45843 | L26: 45840 | M26: PIX ITAU ALV | N26: 336 | O26: 336 | P26: B | Q26: 18 | R26: 02.01.01 | S26: Acabamento Externo | T26: DESPESAS FONECEDORES | V26: ITAU ALV | W26: Sem Origem | X26: Pagamento de Ordens de Serviço:1104, | Y26: =IF(L26="",K26,L26) -> 45840 | Z26: =TEXT(Y26,"MMMM") -> julho
A27: 1154 | B27: 1154 | C27: 2736 | D27: 1 | E27: 2T-OP288_x000D_ -1/1 | F27: 2569 | H27: DIVINO-ACABAMENTO | I27: 45831 | J27: 45831 | K27: 45843 | L27: 45840 | M27: PIX ITAU ALV | N27: 382.2 | O27: 382.2 | P27: B | Q27: 18 | R27: 02.01.01 | S27: Acabamento Externo | T27: DESPESAS FONECEDORES | V27: ITAU ALV | W27: Sem Origem | X27: Pagamento de Ordens de Serviço:1105, | Y27: =IF(L27="",K27,L27) -> 45840 | Z27: =TEXT(Y27,"MMMM") -> julho
A28: 1154 | B28: 1154 | C28: 2737 | D28: 1 | E28: 2T-OP290_x000D_ -1/1 | F28: 2569 | H28: DIVINO-ACABAMENTO | I28: 45832 | J28: 45832 | K28: 45843 | L28: 45840 | M28: PIX ITAU ALV | N28: 550.2 | O28: 550.2 | P28: B | Q28: 18 | R28: 02.01.01 | S28: Acabamento Externo | T28: DESPESAS FONECEDORES | V28: ITAU ALV | W28: Sem Origem | X28: Pagamento de Ordens de Serviço:1106, | Y28: =IF(L28="",K28,L28) -> 45840 | Z28: =TEXT(Y28,"MMMM") -> julho
A29: 1154 | B29: 1154 | C29: 2742 | D29: 1 | E29: 2T-OP328_x000D_ -1/1 | F29: 2569 | H29: DIVINO-ACABAMENTO | I29: 45832 | J29: 45832 | K29: 45843 | L29: 45840 | M29: PIX ITAU ALV | N29: 646.8 | O29: 646.8 | P29: B | Q29: 18 | R29: 02.01.01 | S29: Acabamento Externo | T29: DESPESAS FONECEDORES | V29: ITAU ALV | W29: Sem Origem | X29: Pagamento de Ordens de Serviço:1107, | Y29: =IF(L29="",K29,L29) -> 45840 | Z29: =TEXT(Y29,"MMMM") -> julho
A30: 1154 | B30: 1154 | C30: 2761 | D30: 1 | E30: 2T-OP325_x000D_ -1/1 | F30: 2569 | H30: DIVINO-ACABAMENTO | I30: 45833 | J30: 45833 | K30: 45843 | L30: 45840 | M30: PIX ITAU ALV | N30: 525 | O30: 525 | P30: B | Q30: 18 | R30: 02.01.01 | S30: Acabamento Externo | T30: DESPESAS FONECEDORES | V30: ITAU ALV | W30: Sem Origem | X30: Pagamento de Ordens de Serviço:1117, | Y30: =IF(L30="",K30,L30) -> 45840 | Z30: =TEXT(Y30,"MMMM") -> julho
A31: 1154 | B31: 1154 | C31: 2769 | D31: 1 | E31: 2T-OP280_x000D_ -1/1 | F31: 2569 | H31: DIVINO-ACABAMENTO | I31: 45835 | J31: 45835 | K31: 45843 | L31: 45840 | M31: PIX ITAU ALV | N31: 478.8 | O31: 478.8 | P31: B | Q31: 18 | R31: 02.01.01 | S31: Acabamento Externo | T31: DESPESAS FONECEDORES | V31: ITAU ALV | W31: Sem Origem | X31: Pagamento de Ordens de Serviço:1118, | Y31: =IF(L31="",K31,L31) -> 45840 | Z31: =TEXT(Y31,"MMMM") -> julho
A32: 1154 | B32: 1154 | C32: 2771 | D32: 1 | E32: 2T-OP269_x000D_ -1/1 | F32: 2569 | H32: DIVINO-ACABAMENTO | I32: 45835 | J32: 45835 | K32: 45845 | L32: 45840 | M32: PIX ITAU ALV | N32: 762.3 | O32: 762.3 | P32: B | Q32: 18 | R32: 02.01.01 | S32: Acabamento Externo | T32: DESPESAS FONECEDORES | V32: ITAU ALV | W32: Sem Origem | Y32: =IF(L32="",K32,L32) -> 45840 | Z32: =TEXT(Y32,"MMMM") -> julho
A33: 1154 | B33: 1154 | C33: 2778 | D33: 1 | E33: 2T-OP333_x000D_ -1/1 | F33: 2569 | H33: DIVINO-ACABAMENTO | I33: 45839 | J33: 45839 | K33: 45843 | L33: 45840 | M33: PIX ITAU ALV | N33: 386.4 | O33: 386.4 | P33: B | Q33: 18 | R33: 02.01.01 | S33: Acabamento Externo | T33: DESPESAS FONECEDORES | V33: ITAU ALV | W33: Sem Origem | X33: Pagamento de Ordens de Serviço:1119, | Y33: =IF(L33="",K33,L33) -> 45840 | Z33: =TEXT(Y33,"MMMM") -> julho
A34: 1154 | B34: 1154 | C34: 2748 | D34: 1 | E34: 2T-OP338_x000D_ -1/1 | F34: 2142 | H34: ADRIANO-FACÇÃO | I34: 45832 | J34: 45832 | K34: 45845 | L34: 45841 | M34: PIX ITAU ALV | N34: 6440 | O34: 6440 | P34: B | Q34: 21 | R34: 02.01.04 | S34: Facção | T34: DESPESAS FONECEDORES | V34: ITAU ALV | W34: Sem Origem | X34: Pagamento de Ordens de Serviço:1108, | Y34: =IF(L34="",K34,L34) -> 45841 | Z34: =TEXT(Y34,"MMMM") -> julho
A35: 1154 | B35: 1154 | C35: 2842 | D35: 1 | E35: 45658 | F35: 1991 | H35: DESPESAS ESCRITORIO | I35: 45841 | J35: 45841 | K35: 45841 | L35: 45841 | M35: CARTÃO DÉBITO | N35: 20.18 | O35: 20.18 | P35: B | Q35: 72 | R35: 02.03.03 | S35: Alimentação | T35: CODI.COM JEANS | V35: ITAU ALV | W35: Sem Origem | X35: Pão dia 01/07 | Y35: =IF(L35="",K35,L35) -> 45841 | Z35: =TEXT(Y35,"MMMM") -> julho
A36: 1154 | B36: 1154 | C36: 2843 | D36: 1 | E36: 45658 | F36: 1991 | H36: DESPESAS ESCRITORIO | I36: 45841 | J36: 45841 | K36: 45841 | L36: 45841 | M36: CARTÃO DÉBITO | N36: 45.99 | O36: 45.99 | P36: B | Q36: 29 | R36: 02.01.12 | S36: Outros Insumos | T36: CODI.COM JEANS | V36: ITAU ALV | W36: Sem Origem | X36: Despesas repassadas Lourival | Y36: =IF(L36="",K36,L36) -> 45841 | Z36: =TEXT(Y36,"MMMM") -> julho
A37: 1154 | B37: 1154 | C37: 2844 | D37: 1 | E37: 45658 | F37: 1991 | H37: DESPESAS ESCRITORIO | I37: 45841 | J37: 45841 | K37: 45841 | L37: 45841 | M37: DINHEIRO | N37: 28 | O37: 28 | P37: B | Q37: 54 | R37: 02.02.24 | S37: Manutenção de Veiculos e Estacionamento | T37: CODI.COM JEANS | V37: ITAU ALV | W37: Sem Origem | X37: Troca de Óleo Moto | Y37: =IF(L37="",K37,L37) -> 45841 | Z37: =TEXT(Y37,"MMMM") -> julho
A38: 1154 | B38: 1154 | C38: 2845 | D38: 1 | E38: 45658 | F38: 1991 | H38: DESPESAS ESCRITORIO | I38: 45841 | J38: 45841 | K38: 45841 | L38: 45841 | M38: CARTÃO DÉBITO | N38: 238.59 | O38: 238.59 | P38: B | Q38: 35 | R38: 02.02.05 | S38: Combustíveis | T38: CODI.COM JEANS | V38: ITAU ALV | W38: Sem Origem | X38: Combustível Carro | Y38: =IF(L38="",K38,L38) -> 45841 | Z38: =TEXT(Y38,"MMMM") -> julho
A39: 1154 | B39: 1154 | C39: 2846 | D39: 1 | E39: 45658 | F39: 1991 | H39: DESPESAS ESCRITORIO | I39: 45841 | J39: 45841 | K39: 45841 | L39: 45841 | M39: CARTÃO DÉBITO | N39: 155.86 | O39: 155.86 | P39: B | Q39: 35 | R39: 02.02.05 | S39: Combustíveis | T39: CODI.COM JEANS | V39: ITAU ALV | W39: Sem Origem | X39: Combustível Carro | Y39: =IF(L39="",K39,L39) -> 45841 | Z39: =TEXT(Y39,"MMMM") -> julho
A40: 1154 | B40: 1154 | C40: 2847 | D40: 1 | E40: 45658 | F40: 1991 | H40: DESPESAS ESCRITORIO | I40: 45841 | J40: 45841 | K40: 45841 | L40: 45841 | M40: CARTÃO DÉBITO | N40: 42.8 | O40: 42.8 | P40: B | Q40: 29 | R40: 02.01.12 | S40: Outros Insumos | T40: CODI.COM JEANS | V40: ITAU ALV | W40: Sem Origem | Y40: =IF(L40="",K40,L40) -> 45841 | Z40: =TEXT(Y40,"MMMM") -> julho
...

Sheet CONTAS A PAGAR
A1: EMP. CADASTRO | B1: EMP.REFERENTE | C1: ID | D1: ID.ITEM | E1: DOCUMENTO | F1: COD. PESSOA | G1: CNPJ | H1: PESSOA | I1: DT. CAD. | J1: DT. EMISSÃO | K1: DT. VENC. | L1: DT. BAIXA | M1: FORMA PAGTO. | N1: VALOR | O1: VALOR PAGO | P1: SIT | Q1: ID.PL.CONTAS | R1: COD. PL CONTAS | S1: PLANO DE CONTAS | T1: CENTRO DE CUSTO | U1: COD.CONTA | V1: CONTA | W1: ORIGEM CAD.PESSOAS | X1: OBS.: | Y1: MÊS | Z1: MÊS TEXTO
A2: 1154 | B2: 1154 | C2: 582 | D2: 3 | E2: 00037384_x000D_ 7-3/3 | F2: 1976 | G2: 61.520.607/0018-35 | H2: SANTISTA TEXTIL | I2: 45565 | J2: 45565 | K2: 45658 | L2: 45656 | M2: BOLETO BANCÁRIO | N2: 3154.33 | O2: 3154.33 | P2: B | Q2: 26 | R2: 02.01.09 | S2: Tecidos | T2: CODI.COM JEANS | V2: ITAU ALV | W2: Sem Origem
A3: 1154 | B3: 1154 | C3: 1095 | D3: 1 | E3: 45658 | F3: 1984 | H3: SHEILA ETIQUETAS | I3: 45637 | J3: 45637 | K3: 45658 | L3: 45656 | M3: BOLETO BANCÁRIO | N3: 430 | O3: 430 | P3: B | Q3: 23 | R3: 02.01.06 | S3: Aviamento | T3: CODI.COM JEANS | V3: ITAU ALV | W3: Sem Origem
A4: 1154 | B4: 1154 | C4: 797 | D4: 1 | E4: OP109-1/_x000D_ 1 | F4: 1957 | H4: ROGERIO - TRAVETE | I4: 45594 | J4: 45594 | K4: 45662 | L4: 45665 | M4: PIX ITAU ALV | N4: 157 | O4: 157 | P4: B | Q4: 27 | R4: 02.01.10 | S4: Travete | T4: DESPESAS FONECEDORES | V4: ITAU ALV | W4: Sem Origem
A5: 1154 | B5: 1154 | C5: 798 | D5: 1 | E5: OP109-1/_x000D_ 1 | F5: 1965 | H5: SILMA - ACABAMENTO | I5: 45594 | J5: 45594 | K5: 45662 | L5: 45649 | M5: PIX ITAU ALV | N5: 345.4 | O5: 345.4 | P5: B | Q5: 18 | R5: 02.01.01 | S5: Acabamento Externo | T5: DESPESAS FONECEDORES | V5: ITAU ALV | W5: Sem Origem
A6: 1154 | B6: 1154 | C6: 807 | D6: 1 | E6: OP112-1/_x000D_ 1 | F6: 1957 | H6: ROGERIO - TRAVETE | I6: 45594 | J6: 45594 | K6: 45662 | L6: 45637 | M6: PIX ITAU ALV | N6: 147 | O6: 147 | P6: B | Q6: 27 | R6: 02.01.10 | S6: Travete | T6: DESPESAS FONECEDORES | V6: ITAU ALV | W6: Sem Origem | X6: compras mês
A7: 1154 | B7: 1154 | C7: 808 | D7: 1 | E7: OP112-1/_x000D_ 1 | F7: 1965 | H7: SILMA - ACABAMENTO | I7: 45594 | J7: 45594 | K7: 45662 | L7: 45649 | M7: PIX ITAU ALV | N7: 323.4 | O7: 323.4 | P7: B | Q7: 18 | R7: 02.01.01 | S7: Acabamento Externo | T7: DESPESAS FONECEDORES | V7: ITAU ALV | W7: Sem Origem
A8: 1154 | B8: 1154 | C8: 897 | D8: 1 | E8: OP125-1/_x000D_ 1 | F8: 1957 | H8: ROGERIO - TRAVETE | I8: 45602 | J8: 45602 | K8: 45662 | L8: 45665 | M8: PIX ITAU ALV | N8: 700 | O8: 700 | P8: B | Q8: 27 | R8: 02.01.10 | S8: Travete | T8: DESPESAS FONECEDORES | V8: ITAU ALV | W8: Sem Origem | X8: Pagamento de Ordens de Serviço:420,
A9: 1154 | B9: 1154 | C9: 898 | D9: 1 | E9: OP125-1/_x000D_ 1 | F9: 1965 | H9: SILMA - ACABAMENTO | I9: 45602 | J9: 45602 | K9: 45662 | L9: 45649 | M9: PIX ITAU ALV | N9: 1540 | O9: 1540 | P9: B | Q9: 18 | R9: 02.01.01 | S9: Acabamento Externo | T9: DESPESAS FONECEDORES | V9: ITAU ALV | W9: Sem Origem | X9: Pagamento de Ordens de Serviço:475,
A10: 1154 | B10: 1154 | C10: 929 | D10: 1 | E10: OP126-1/_x000D_ 1 | F10: 1957 | H10: ROGERIO - TRAVETE | I10: 45607 | J10: 45607 | K10: 45662 | L10: 45665 | M10: PIX ITAU ALV | N10: 120 | O10: 120 | P10: B | Q10: 27 | R10: 02.01.10 | S10: Travete | T10: DESPESAS FONECEDORES | V10: ITAU ALV | W10: Sem Origem | X10: Pagamento de Ordens de Serviço:478,
A11: 1154 | B11: 1154 | C11: 930 | D11: 1 | E11: OP126-1/_x000D_ 1 | F11: 1965 | H11: SILMA - ACABAMENTO | I11: 45607 | J11: 45607 | K11: 45662 | L11: 45649 | M11: PIX ITAU ALV | N11: 264 | O11: 264 | P11: B | Q11: 18 | R11: 02.01.01 | S11: Acabamento Externo | T11: DESPESAS FONECEDORES | V11: ITAU ALV | W11: Sem Origem
A12: 1154 | B12: 1154 | C12: 935 | D12: 1 | E12: OP128-1/_x000D_ 1 | F12: 1957 | H12: ROGERIO - TRAVETE | I12: 45608 | J12: 45608 | K12: 45662 | L12: 45665 | M12: PIX ITAU ALV | N12: 423 | O12: 423 | P12: B | Q12: 27 | R12: 02.01.10 | S12: Travete | T12: DESPESAS FONECEDORES | V12: ITAU ALV | W12: Sem Origem
A13: 1154 | B13: 1154 | C13: 945 | D13: 1 | E13: OP131-1/_x000D_ 1 | F13: 1957 | H13: ROGERIO - TRAVETE | I13: 45608 | J13: 45608 | K13: 45662 | L13: 45665 | M13: PIX ITAU ALV | N13: 77 | O13: 77 | P13: B | Q13: 27 | R13: 02.01.10 | S13: Travete | T13: DESPESAS FONECEDORES | V13: ITAU ALV | W13: Sem Origem
A14: 1154 | B14: 1154 | C14: 946 | D14: 1 | E14: OP131-1/_x000D_ 1 | F14: 1965 | H14: SILMA - ACABAMENTO | I14: 45608 | J14: 45608 | K14: 45662 | L14: 45638 | M14: PIX ITAU ALV | N14: 169.4 | O14: 169.4 | P14: B | Q14: 18 | R14: 02.01.01 | S14: Acabamento Externo | T14: DESPESAS FONECEDORES | V14: ITAU ALV | W14: Sem Origem
A15: 1154 | B15: 1154 | C15: 949 | D15: 1 | E15: OP132-1/_x000D_ 1 | F15: 1957 | H15: ROGERIO - TRAVETE | I15: 45608 | J15: 45608 | K15: 45662 | L15: 45665 | M15: PIX ITAU ALV | N15: 300 | O15: 300 | P15: B | Q15: 27 | R15: 02.01.10 | S15: Travete | T15: DESPESAS FONECEDORES | V15: ITAU ALV | W15: Sem Origem
A16: 1154 | B16: 1154 | C16: 954 | D16: 1 | E16: OP133-1/_x000D_ 1 | F16: 1957 | H16: ROGERIO - TRAVETE | I16: 45608 | J16: 45608 | K16: 45662 | L16: 45665 | M16: PIX ITAU ALV | N16: 40 | O16: 40 | P16: B | Q16: 27 | R16: 02.01.10 | S16: Travete | T16: DESPESAS FONECEDORES | V16: ITAU ALV | W16: Sem Origem
A17: 1154 | B17: 1154 | C17: 973 | D17: 1 | E17: OP134-1/_x000D_ 1 | F17: 1957 | H17: ROGERIO - TRAVETE | I17: 45614 | J17: 45614 | K17: 45662 | L17: 45665 | M17: PIX ITAU ALV | N17: 434 | O17: 434 | P17: B | Q17: 27 | R17: 02.01.10 | S17: Travete | T17: DESPESAS FONECEDORES | V17: ITAU ALV | W17: Sem Origem
A18: 1154 | B18: 1154 | C18: 976 | D18: 1 | E18: OP135-1/_x000D_ 1 | F18: 1957 | H18: ROGERIO - TRAVETE | I18: 45614 | J18: 45614 | K18: 45662 | L18: 45637 | M18: PIX ITAU ALV | N18: 45 | O18: 45 | P18: B | Q18: 27 | R18: 02.01.10 | S18: Travete | T18: DESPESAS FONECEDORES | V18: ITAU ALV | W18: Sem Origem
A19: 1154 | B19: 1154 | C19: 977 | D19: 1 | E19: OP135-1/_x000D_ 1 | F19: 1965 | H19: SILMA - ACABAMENTO | I19: 45614 | J19: 45614 | K19: 45662 | L19: 45649 | M19: PIX ITAU ALV | N19: 99 | O19: 99 | P19: B | Q19: 18 | R19: 02.01.01 | S19: Acabamento Externo | T19: DESPESAS FONECEDORES | V19: ITAU ALV | W19: Sem Origem
A20: 1154 | B20: 1154 | C20: 992 | D20: 1 | E20: OP136-1/_x000D_ 1 | F20: 1957 | H20: ROGERIO - TRAVETE | I20: 45618 | J20: 45618 | K20: 45662 | L20: 45630 | M20: PIX ITAU ALV | N20: 430 | O20: 430 | P20: B | Q20: 27 | R20: 02.01.10 | S20: Travete | T20: DESPESAS FONECEDORES | V20: ITAU ALV | W20: Sem Origem
A21: 1154 | B21: 1154 | C21: 993 | D21: 1 | E21: OP136-1/_x000D_ 1 | F21: 1965 | H21: SILMA - ACABAMENTO | I21: 45618 | J21: 45618 | K21: 45662 | L21: 45649 | M21: PIX ITAU ALV | N21: 946 | O21: 946 | P21: B | Q21: 18 | R21: 02.01.01 | S21: Acabamento Externo | T21: DESPESAS FONECEDORES | V21: ITAU ALV | W21: Sem Origem
A22: 1154 | B22: 1154 | C22: 995 | D22: 1 | E22: OP137-1/_x000D_ 1 | F22: 1957 | H22: ROGERIO - TRAVETE | I22: 45618 | J22: 45618 | K22: 45662 | L22: 45665 | M22: PIX ITAU ALV | N22: 140 | O22: 140 | P22: B | Q22: 27 | R22: 02.01.10 | S22: Travete | T22: DESPESAS FONECEDORES | V22: ITAU ALV | W22: Sem Origem
... A29: 1154 | B29: 1154 | C29: 869 | D29: 1 | E29: OP120-1/_x000D_ 1 | F29: 1957 | H29: ROGERIO - TRAVETE | I29: 45600 | J29: 45600 | K29: 45662 | L29: 45665 | M29: PIX ITAU ALV | N29: 247 | O29: 247 | P29: B | Q29: 27 | R29: 02.01.10 | S29: Travete | T29: DESPESAS FONECEDORES | V29: ITAU ALV | W29: Sem Origem
A30: 1154 | B30: 1154 | C30: 772 | D30: 3 | E30: 45780 | F30: 2152 | H30: LUCAS/ CONTADOR | I30: 45587 | J30: 45587 | K30: 45662 | L30: 45688 | M30: PIX ITAU ALV | N30: 920 | O30: 920 | P30: B | Q30: 39 | R30: 02.02.09 | S30: Advogados - Honorários | T30: DESPESAS MENSAIS | V30: ITAU ALV | W30: Sem Origem
A31: 1154 | B31: 1154 | C31: 759 | D31: 3 | E31: 45780 | F31: 2110 | H31: BORGES ESTOQUE | I31: 45587 | J31: 45587 | K31: 45663 | L31: 45664 | M31: PIX ITAU ALV | N31: 2100 | O31: 2100 | P31: B | Q31: 83 | R31: 02.03.13 | S31: Salário e Ordenados | T31: DESPESA COLABORADORES | V31: ITAU ALV | W31: Sem Origem | X31: ERREJOTA
A32: 1154 | B32: 1154 | C32: 761 | D32: 3 | E32: 45780 | F32: 2060 | H32: AILTON CORTADOR | I32: 45587 | J32: 45587 | K32: 45663 | L32: 45664 | M32: PIX ITAU ALV | N32: 2274 | O32: 2274 | P32: B | Q32: 83 | R32: 02.03.13 | S32: Salário e Ordenados | T32: DESPESA COLABORADORES | V32: ITAU ALV | W32: Sem Origem | X32: Pagamento de Ordens de Serviço:369,
A33: 1154 | B33: 1154 | C33: 762 | D33: 3 | E33: 45780 | F33: 2186 | H33: JOSÉ HAMILTON CORTADOR | I33: 45587 | J33: 45587 | K33: 45663 | L33: 45664 | M33: PIX ITAU ALV | N33: 1400 | O33: 1400 | P33: B | Q33: 83 | R33: 02.03.13 | S33: Salário e Ordenados | T33: DESPESA COLABORADORES | V33: ITAU ALV | W33: Sem Origem | X33: Pagamento de Ordens de Serviço:395,
A34: 1154 | B34: 1154 | C34: 763 | D34: 3 | E34: 45780 | F34: 2063 | H34: DELVA GERENTE DO ESTOQUE | I34: 45587 | J34: 45587 | K34: 45663 | L34: 45664 | M34: PIX ITAU ALV | N34: 1700 | O34: 1700 | P34: B | Q34: 83 | R34: 02.03.13 | S34: Salário e Ordenados | T34: DESPESA COLABORADORES | V34: ITAU ALV | W34: Sem Origem | X34: Pagamento de Ordens de Serviço:401,
A35: 1154 | B35: 1154 | C35: 764 | D35: 3 | E35: 45780 | F35: 2064 | H35: WENDER WALLAN | I35: 45587 | J35: 45587 | K35: 45663 | L35: 45664 | M35: PIX ITAU ALV | N35: 2600 | O35: 2600 | P35: B | Q35: 83 | R35: 02.03.13 | S35: Salário e Ordenados | T35: DESPESA COLABORADORES | V35: ITAU ALV | W35: Sem Origem | X35: Pagamento de Ordens de Serviço:410,
A36: 1154 | B36: 1154 | C36: 766 | D36: 2 | E36: 45749 | F36: 828 | H36: PAULO ESTOQUE ENTREGAS | I36: 45587 | J36: 45587 | K36: 45663 | L36: =K36 -> 45663 | M36: PIX ITAU ALV | N36: 1800 | P36: S | Q36: 83 | R36: 02.03.13 | S36: Salário e Ordenados | T36: DESPESA COLABORADORES | V36: ITAU ALV | W36: Sem Origem | X36: Pagamento de Ordens de Serviço:413,
A37: 1154 | B37: 1154 | C37: 767 | D37: 3 | E37: 45780 | F37: 2120 | H37: GABY VENDAS LOJA | I37: 45587 | J37: 45587 | K37: 45663 | L37: =K37 -> 45663 | M37: PIX ITAU ALV | N37: 1412 | P37: S | Q37: 83 | R37: 02.03.13 | S37: Salário e Ordenados | T37: DESPESA COLABORADORES | V37: ITAU ALV | W37: Sem Origem | X37: Pagamento de Ordens de Serviço:415,
A38: 1154 | B38: 1154 | C38: 769 | D38: 3 | E38: 45780 | F38: 2180 | H38: ADRIANA VENDAS FÁBRICA | I38: 45587 | J38: 45587 | K38: 45663 | L38: =K38 -> 45663 | M38: PIX ITAU ALV | N38: 1412 | P38: S | Q38: 83 | R38: 02.03.13 | S38: Salário e Ordenados | T38: DESPESA COLABORADORES | V38: ITAU ALV | W38: Sem Origem | X38: Pagamento de Ordens de Serviço:418,
A39: 1154 | B39: 1154 | C39: 770 | D39: 3 | E39: 45780 | F39: 2112 | H39: MARIA EDUARDA VENDAS FÁBRICA | I39: 45587 | J39: 45587 | K39: 45663 | L39: =K39 -> 45663 | M39: PIX ITAU ALV | N39: 1412 | P39: S | Q39: 83 | R39: 02.03.13 | S39: Salário e Ordenados | T39: DESPESA COLABORADORES | V39: ITAU ALV | W39: Sem Origem | X39: Pagamento de Ordens de Serviço:427,
A40: 1154 | B40: 1154 | C40: 773 | D40: 3 | E40: 45780 | F40: 2071 | H40: DANIEL ENNOS | I40: 45587 | J40: 45587 | K40: 45663 | L40: =K40 -> 45663 | M40: PIX ITAU ALV | N40: 4500 | P40: S | Q40: 83 | R40: 02.03.13 | S40: Salário e Ordenados | T40: DESPESA COLABORADORES | V40: ITAU ALV | W40: Sem Origem | X40: Pagamento de Ordens de Serviço:430,
A41: 1154 | B41: 1154 | C41: 774 | D41: 3 | E41: 45780 | F41: 2070 | H41: LUCAS KOJIMA | I41: 45587 | J41: 45587 | K41: 45663 | L41: 45664 | M41: PIX ITAU ALV | N41: 1500 | O41: 1500 | P41: B | Q41: 83 | R41: 02.03.13 | S41: Salário e Ordenados | T41: DESPESA COLABORADORES | V41: ITAU ALV | W41: Sem Origem | X41: Pagamento de Ordens de Serviço:433,
A42: 1154 | B42: 1154 | C42: 902 | D42: 2 | E42: 45718 | F42: 2260 | H42: THAIS VENDAS FABRICA | I42: 45603 | J42: 45603 | K42: 45663 | L42: =K42 -> 45663 | M42: PIX ITAU ALV | N42: 1412 | P42: S | Q42: 83 | R42: 02.03.13 | S42: Salário e Ordenados | T42: DESPESA COLABORADORES | V42: ITAU ALV | W42: Sem Origem | X42: Pagamento de Ordens de Serviço:436,
A43: 1154 | B43: 1154 | C43: 1020 | D43: 1 | E43: OP139QS_x000D_ -1/1 | F43: 1953 | H43: CIDA - FACÇÃO | I43: 45625 | J43: 45625 | K43: 45663 | L43: 45636 | M43: PIX ITAU ALV | N43: 517.5 | O43: 517.5 | P43: B | Q43: 21 | R43: 02.01.04 | S43: Facção | T43: DESPESAS FONECEDORES | V43: ITAU ALV | W43: Sem Origem | X43: Pagamento de Ordens de Serviço:439,
A44: 1154 | B44: 1154 | C44: 1045 | D44: 1 | E44: OP108-1/_x000D_ 1 | F44: 1957 | H44: ROGERIO - TRAVETE | I44: 45635 | J44: 45635 | K44: 45663 | L44: 45665 | M44: PIX ITAU ALV | N44: 260 | O44: 260 | P44: B | Q44: 27 | R44: 02.01.10 | S44: Travete | T44: DESPESAS FONECEDORES | V44: ITAU ALV | W44: Sem Origem | X44: Pagamento de Ordens de Serviço:450,
A45: 1154 | B45: 1154 | C45: 1048 | D45: 1 | E45: OP111-1/_x000D_ 1 | F45: 1957 | H45: ROGERIO - TRAVETE | I45: 45635 | J45: 45635 | K45: 45663 | L45: 45665 | M45: PIX ITAU ALV | N45: 325 | O45: 325 | P45: B | Q45: 27 | R45: 02.01.10 | S45: Travete | T45: DESPESAS FONECEDORES | V45: ITAU ALV | W45: Sem Origem | X45: Pagamento de Ordens de Serviço:453,
A46: 1154 | B46: 1154 | C46: 1049 | D46: 1 | E46: OP114-1/_x000D_ 1 | F46: 1957 | H46: ROGERIO - TRAVETE | I46: 45635 | J46: 45635 | K46: 45663 | L46: 45665 | M46: PIX ITAU ALV | N46: 40 | O46: 40 | P46: B | Q46: 27 | R46: 02.01.10 | S46: Travete | T46: DESPESAS FONECEDORES | V46: ITAU ALV | W46: Sem Origem | X46: Pagamento de Ordens de Serviço:454,
...

Sheet CONTAS A RECEBER
A1: DOCUMENTO | B1: CNPJ | C1: PESSOA | D1: DT.CAD. | E1: DT. VENC. | F1: DT. BAIXA | G1: FORMA PGTO. | H1: VALOR | I1: VALOR _x000D_ RECEBIDO | J1: REC. | K1: ID PL.CONTAS | L1: COD.PL.CONTAS | M1: PLANO DE CONTAS | N1: SIT | O1: PORTADOR | P1: COD.CONTA | Q1: CONTA | R1: OBS.: | S1: Nº NF-E | T1: INF. FATURA NF-E | U1: Nº NSU | V1: MÊS
A2: P1436/1 | C2: PATRICIA MARQUES | D2: 45646 | E2: 45676 | F2: 45659 | G2: LINK REDE | H2: 5625 | I2: 5625 | J2: 1201 | K2: 3 | L2: 01.01.01 | M2: Vendas | N2: B | P2: 2 | Q2: ITAU ALV | V2: =TEXT(F2,"MMMM") -> janeiro
